Workbook

Sheet 01
A2: Stock Inventory Report of JULY 2026
S4: Date | T4: 45839
A5: Nº | B5: Item Name | D5: Par Stock | E5: Opening | H5: Request | K5: In Stock | N5: Lost /Spoil | O5: Transfer out | P5: Cost of FOC | Q5: Cost of Sale | R5: Consumption | S5: Cost of Sale | T5: Closing | W5: Sale Report
B6: English | C6: Khmer | E6: ដើមគ្រា | H6: បើកចូល | K6: ទំនិញមានក្នុងស្តុក | N6: ខូច/បាត់ | O6: ផ្ទេរចេញ | P6: ថ្លៃដើមព្រី | Q6: ថ្លៃដើមលក់ | R6: ថ្លៃដើម | S6: ថ្លៃដើមលក់ | T6: ចុងគ្រា | W6: Daily | AA6: Monthly
B7: Soft Drink | E7: Qtt | F7: U.P | G7: Amount | H7: Qtt | I7: U.P | J7: Amount | K7: Qtt | L7: U.P | M7: Amount | N7: Qtt | O7: Amount | P7: Qtt | Q7: Amount | R7: ថ្លៃដើមលក់ | S7: Amount | T7: Qtt | U7: U.P | V7: Amount | Y7: Qty | Z7: Amount | AA7: Qty | AB7: Amount
A8: 1 | B8: Cocacola Classic 330ml (24cans) | C8: កូកា ក្លាស៊ិក (កំប៉ុង៣៣០មម) | D8: 48 | E8: 1 | F8: =8.7/24 -> 0.3625 | G8: =+E8*F8 -> 0.3625 | J8: =+H8*I8 -> 0 | K8: =+E8+H8 -> 1 | L8: =IF(K8=0,,M8/K8) -> 0.3625 | M8: =+J8+G8 -> 0.3625 | O8: =+L8*N8 -> 0 | Q8: =+P8*L8 -> 0 | S8: =+R8*L8 -> 0 | T8: =+K8-N8-P8-R8 -> 1 | U8: =IF(T8=0,,V8/T8) -> 0.3625 | V8: =+T8*L8 -> 0.3625 | W8: =+$B$8 -> Cocacola Classic 330ml (24cans) | Y8: =+$R$8 -> 0 | Z8: =+Y8*1 -> 0 | AA8: =+Y8 -> 0 | AB8: =+Z8 -> 0
A9: =+A8+1 -> 2 | B9: Cocacola Zero 330ml (24cans) | C9: កូកា សេរ៉ូ (កំប៉ុង៣៣០មម) | D9: 48 | E9: 18 | F9: =8.7/24 -> 0.3625 | G9: =+E9*F9 -> 6.525 | J9: =+H9*I9 -> 0 | K9: =+E9+H9 -> 18 | L9: =IF(K9=0,,M9/K9) -> 0.3625 | M9: =+J9+G9 -> 6.525 | O9: =+L9*N9 -> 0 | Q9: =+P9*L9 -> 0 | S9: =+R9*L9 -> 0 | T9: =+K9-N9-P9-R9 -> 18 | U9: =IF(T9=0,,V9/T9) -> 0.3625 | V9: =+T9*L9 -> 6.525 | W9: =+$B$9 -> Cocacola Zero 330ml (24cans) | Y9: =+$R$9 -> 0 | Z9: =+Y9*1 -> 0 | AA9: =+Y9 -> 0 | AB9: =+Z9 -> 0
A10: =+A9+1 -> 3 | B10: Cocacola Light 330ml (24cans) | C10: កូកា ឡៃ (កំប៉ុង៣៣០មម) | D10: 48 | E10: 11 | F10: =8.7/24 -> 0.3625 | G10: =+E10*F10 -> 3.9875 | J10: =+H10*I10 -> 0 | K10: =+E10+H10 -> 11 | L10: =IF(K10=0,,M10/K10) -> 0.3625 | M10: =+J10+G10 -> 3.9875 | O10: =+L10*N10 -> 0 | Q10: =+P10*L10 -> 0 | S10: =+R10*L10 -> 0 | T10: =+K10-N10-P10-R10 -> 11 | U10: =IF(T10=0,,V10/T10) -> 0.3625 | V10: =+T10*L10 -> 3.9875 | W10: =+$B$10 -> Cocacola Light 330ml (24cans) | Y10: =+$R$10 -> 0 | Z10: =+Y10*1 -> 0 | AA10: =+Y10 -> 0 | AB10: =+Z10 -> 0
A11: =+A10+1 -> 4 | B11: Sprite 330ml (24cans) | C11: ស្ព្រៃ (កំប៉ុង៣៣០មម) | D11: 48 | E11: 2 | F11: =8.7/24 -> 0.3625 | G11: =+E11*F11 -> 0.725 | J11: =+H11*I11 -> 0 | K11: =+E11+H11 -> 2 | L11: =IF(K11=0,,M11/K11) -> 0.3625 | M11: =+J11+G11 -> 0.725 | O11: =+L11*N11 -> 0 | Q11: =+P11*L11 -> 0 | S11: =+R11*L11 -> 0 | T11: =+K11-N11-P11-R11 -> 2 | U11: =IF(T11=0,,V11/T11) -> 0.3625 | V11: =+T11*L11 -> 0.725 | W11: =+$B$11 -> Sprite 330ml (24cans) | Y11: =+$R$11 -> 0 | Z11: =+Y11*1 -> 0 | AA11: =+Y11 -> 0 | AB11: =+Z11 -> 0
A12: =+A11+1 -> 5 | B12: Schweppes Soda Water 330ml (24cans) | C12: ទឹកសូដា (កំប៉ុង៣៣០មម) | D12: 48 | E12: 14 | F12: =8.7/24 -> 0.3625 | G12: =+E12*F12 -> 5.075 | J12: =+H12*I12 -> 0 | K12: =+E12+H12 -> 14 | L12: =IF(K12=0,,M12/K12) -> 0.3625 | M12: =+J12+G12 -> 5.075 | O12: =+L12*N12 -> 0 | Q12: =+P12*L12 -> 0 | S12: =+R12*L12 -> 0 | T12: =+K12-N12-P12-R12 -> 14 | U12: =IF(T12=0,,V12/T12) -> 0.3625 | V12: =+T12*L12 -> 5.075 | W12: =+$B$12 -> Schweppes Soda Water 330ml (24cans) | Y12: =+$R$12 -> 0 | Z12: =+Y12*1 -> 0 | AA12: =+Y12 -> 0 | AB12: =+Z12 -> 0
A13: =+A12+1 -> 6 | B13: Schweppes Tonic Water 330ml (24cans) | C13: ទឹកតូនិច (កំប៉ុង៣៣០មម) | D13: 48 | E13: 19 | F13: =8.7/24 -> 0.3625 | G13: =+E13*F13 -> 6.8875 | J13: =+H13*I13 -> 0 | K13: =+E13+H13 -> 19 | L13: =IF(K13=0,,M13/K13) -> 0.3625 | M13: =+J13+G13 -> 6.8875 | O13: =+L13*N13 -> 0 | Q13: =+P13*L13 -> 0 | S13: =+R13*L13 -> 0 | T13: =+K13-N13-P13-R13 -> 19 | U13: =IF(T13=0,,V13/T13) -> 0.3625 | V13: =+T13*L13 -> 6.8875 | W13: =+$B$13 -> Schweppes Tonic Water 330ml (24cans) | Y13: =+$R$13 -> 0 | Z13: =+Y13*1 -> 0 | AA13: =+Y13 -> 0 | AB13: =+Z13 -> 0
A14: =+A13+1 -> 7 | B14: Schweppes Ginger Ale 330ml (24cans) | C14: ទឹក Ginger ale (កំប៉ុង៣៣០មម) | D14: 48 | E14: 20 | F14: =8.7/24 -> 0.3625 | G14: =+E14*F14 -> 7.25 | J14: =+H14*I14 -> 0 | K14: =+E14+H14 -> 20 | L14: =IF(K14=0,,M14/K14) -> 0.3625 | M14: =+J14+G14 -> 7.25 | O14: =+L14*N14 -> 0 | Q14: =+P14*L14 -> 0 | S14: =+R14*L14 -> 0 | T14: =+K14-N14-P14-R14 -> 20 | U14: =IF(T14=0,,V14/T14) -> 0.3625 | V14: =+T14*L14 -> 7.25 | W14: =+$B$14 -> Schweppes Ginger Ale 330ml (24cans) | Y14: =+$R$14 -> 0 | Z14: =+Y14*1 -> 0 | AA14: =+Y14 -> 0 | AB14: =+Z14 -> 0
B15: TOTAL SOFT DRINK | D15: =+SUM(D8:D14) -> 336 | E15: =+SUM(E8:E14) -> 85 | G15: =+SUM(G8:G14) -> 30.8125 | H15: =+SUM(H8:H14) -> 0 | J15: =+SUM(J8:J14) -> 0 | K15: =+SUM(K8:K14) -> 85 | M15: =+SUM(M8:M14) -> 30.8125 | N15: =+SUM(N8:N14) -> 0 | O15: =+SUM(O8:O14) -> 0 | P15: =+SUM(P8:P14) -> 0 | Q15: =+SUM(Q8:Q14) -> 0 | R15: =+SUM(R8:R14) -> 0 | S15: =+SUM(S8:S14) -> 0 | T15: =+SUM(T8:T14) -> 85 | V15: =+SUM(V8:V14) -> 30.8125 | W15: =+$B$17 -> Dasani 500ml (24 Btl) | Y15: =+$R$17 -> 1 | Z15: =+Y15*0.5 -> 0.5 | AA15: =+Y15 -> 1 | AB15: =+Z15 -> 0.5
B16: Water | W16: =+$B$20 -> TIGER BEER 330ml CAN | Y16: =+$R$20 -> 0 | Z16: =+Y16*1.25 -> 0 | AA16: =+Y16 -> 0 | AB16: =+Z16 -> 0
A17: =+A14+1 -> 8 | B17: Dasani 500ml (24 Btl) | D17: 48 | E17: 34 | F17: =3.56/24 -> 0.14833333 | G17: =+E17*F17 -> 5.0433333 | J17: =+H17*I17 -> 0 | K17: =+E17+H17 -> 34 | L17: =IF(K17=0,,M17/K17) -> 0.14833333 | M17: =+J17+G17 -> 5.0433333 | O17: =+L17*N17 -> 0 | Q17: =+P17*L17 -> 0 | R17: 1 | S17: =+R17*L17 -> 0.14833333 | T17: =+K17-N17-P17-R17 -> 33 | U17: =IF(T17=0,,V17/T17) -> 0.14833333 | V17: =+T17*L17 -> 4.895 | W17: =+$B$21 -> Heineken 330ml CAN | Y17: =+$R$21 -> 0 | Z17: =+Y17*1.25 -> 0 | AA17: =+Y17 -> 0 | AB17: =+Z17 -> 0
B18: TOTAL Water | D18: =+D17 -> 48 | E18: =+E17 -> 34 | G18: =+G17 -> 5.0433333 | H18: =+H17 -> 0 | J18: =+J17 -> 0 | K18: =+K17 -> 34 | M18: =+M17 -> 5.0433333 | N18: =+N17 -> 0 | O18: =+O17 -> 0 | P18: =+P17 -> 0 | Q18: =+Q17 -> 0 | R18: =+R17 -> 1 | S18: =+S17 -> 0.14833333 | T18: =+T17 -> 33 | V18: =+V17 -> 4.895 | W18: =+B22 -> 0 | Y18: =+$R$22 -> 0 | Z18: =+Y18*1 -> 0 | AA18: =+Y18 -> 0 | AB18: =+Z18 -> 0
B19: Beer | W19: =+B23 -> 0 | Y19: =+$R$23 -> 0 | Z19: =+Y19*1 -> 0 | AA19: =+Y19 -> 0 | AB19: =+Z19 -> 0
A20: =+A19+1 -> 1 | B20: TIGER BEER 330ml CAN | C20: ស្រាបៀរថៃហ្គ័រ (កំប៉ុង ៣៣០មល) | D20: 48 | E20: 32 | F20: 0.48 | G20: =+E20*F20 -> 15.36 | J20: =+H20*I20 -> 0 | K20: =+E20+H20 -> 32 | L20: =IF(K20=0,,M20/K20) -> 0.48 | M20: =+J20+G20 -> 15.36 | O20: =+L20*N20 -> 0 | Q20: =+P20*L20 -> 0 | S20: =+R20*L20 -> 0 | T20: =+K20-N20-P20-R20 -> 32 | U20: =IF(T20=0,,V20/T20) -> 0.48 | V20: =+T20*L20 -> 15.36 | W20: TOTAL | Y20: =+SUM(Y8:Y19) -> 1 | Z20: =+SUM(Z8:Z19) -> 0.5 | AA20: =+SUM(AA8:AA19) -> 1 | AB20: =+SUM(AB8:AB19) -> 0.5
A21: =+A20+1 -> 2 | B21: Heineken 330ml CAN | C21: ស្រាបៀរហេន័រឃិន (កំប៉ុង ៣៣០មល) | D21: 48 | E21: 29 | F21: 0.65 | G21: =+E21*F21 -> 18.85 | J21: =+H21*I21 -> 0 | K21: =+E21+H21 -> 29 | L21: =IF(K21=0,,M21/K21) -> 0.65 | M21: =+J21+G21 -> 18.85 | O21: =+L21*N21 -> 0 | Q21: =+P21*L21 -> 0 | S21: =+R21*L21 -> 0 | T21: =+K21-N21-P21-R21 -> 29 | U21: =IF(T21=0,,V21/T21) -> 0.65 | V21: =+T21*L21 -> 18.85
A22: =+A21+1 -> 3 | G22: =+E22*F22 -> 0 | J22: =+H22*I22 -> 0 | K22: =+E22+H22 -> 0 | L22: =IF(K22=0,,M22/K22) -> 0 | M22: =+J22+G22 -> 0 | O22: =+L22*N22 -> 0 | Q22: =+P22*L22 -> 0 | S22: =+R22*L22 -> 0 | T22: =+K22-N22-P22-R22 -> 0 | U22: =IF(T22=0,,V22/T22) -> 0 | V22: =+T22*L22 -> 0
A23: =+A22+1 -> 4 | G23: =+E23*F23 -> 0 | J23: =+H23*I23 -> 0 | K23: =+E23+H23 -> 0 | L23: =IF(K23=0,,M23/K23) -> 0 | M23: =+J23+G23 -> 0 | O23: =+L23*N23 -> 0 | Q23: =+P23*L23 -> 0 | S23: =+R23*L23 -> 0 | T23: =+K23-N23-P23-R23 -> 0 | U23: =IF(T23=0,,V23/T23) -> 0 | V23: =+T23*L23 -> 0
A24: =+A23+1 -> 5 | G24: =+E24*F24 -> 0 | J24: =+H24*I24 -> 0 | K24: =+E24+H24 -> 0 | L24: =IF(K24=0,,M24/K24) -> 0 | M24: =+J24+G24 -> 0 | O24: =+L24*N24 -> 0 | Q24: =+P24*L24 -> 0 | S24: =+R24*L24 -> 0 | T24: =+K24-N24-P24-R24 -> 0 | U24: =IF(T24=0,,V24/T24) -> 0 | V24: =+T24*L24 -> 0
A25: =+A24+1 -> 6 | G25: =+E25*F25 -> 0 | J25: =+H25*I25 -> 0 | K25: =+E25+H25 -> 0 | L25: =IF(K25=0,,M25/K25) -> 0 | M25: =+J25+G25 -> 0 | O25: =+L25*N25 -> 0 | Q25: =+P25*L25 -> 0 | S25: =+R25*L25 -> 0 | T25: =+K25-N25-P25-R25 -> 0 | U25: =IF(T25=0,,V25/T25) -> 0 | V25: =+T25*L25 -> 0
A26: =+A25+1 -> 7 | G26: =+E26*F26 -> 0 | J26: =+H26*I26 -> 0 | K26: =+E26+H26 -> 0 | L26: =IF(K26=0,,M26/K26) -> 0 | M26: =+J26+G26 -> 0 | O26: =+L26*N26 -> 0 | Q26: =+P26*L26 -> 0 | S26: =+R26*L26 -> 0 | T26: =+K26-N26-P26-R26 -> 0 | U26: =IF(T26=0,,V26/T26) -> 0 | V26: =+T26*L26 -> 0
A27: =+A26+1 -> 8 | G27: =+E27*F27 -> 0 | J27: =+H27*I27 -> 0 | K27: =+E27+H27 -> 0 | L27: =IF(K27=0,,M27/K27) -> 0 | M27: =+J27+G27 -> 0 | O27: =+L27*N27 -> 0 | Q27: =+P27*L27 -> 0 | S27: =+R27*L27 -> 0 | T27: =+K27-N27-P27-R27 -> 0 | U27: =IF(T27=0,,V27/T27) -> 0 | V27: =+T27*L27 -> 0
A28: =+A27+1 -> 9 | G28: =+E28*F28 -> 0 | J28: =+H28*I28 -> 0 | K28: =+E28+H28 -> 0 | L28: =IF(K28=0,,M28/K28) -> 0 | M28: =+J28+G28 -> 0 | O28: =+L28*N28 -> 0 | Q28: =+P28*L28 -> 0 | S28: =+R28*L28 -> 0 | T28: =+K28-N28-P28-R28 -> 0 | U28: =IF(T28=0,,V28/T28) -> 0 | V28: =+T28*L28 -> 0
A29: =+A28+1 -> 10 | G29: =+E29*F29 -> 0 | J29: =+H29*I29 -> 0 | K29: =+E29+H29 -> 0 | L29: =IF(K29=0,,M29/K29) -> 0 | M29: =+J29+G29 -> 0 | O29: =+L29*N29 -> 0 | Q29: =+P29*L29 -> 0 | S29: =+R29*L29 -> 0 | T29: =+K29-N29-P29-R29 -> 0 | U29: =IF(T29=0,,V29/T29) -> 0 | V29: =+T29*L29 -> 0
A30: =+A29+1 -> 11 | G30: =+E30*F30 -> 0 | J30: =+H30*I30 -> 0 | K30: =+E30+H30 -> 0 | L30: =IF(K30=0,,M30/K30) -> 0 | M30: =+J30+G30 -> 0 | O30: =+L30*N30 -> 0 | Q30: =+P30*L30 -> 0 | S30: =+R30*L30 -> 0 | T30: =+K30-N30-P30-R30 -> 0 | U30: =IF(T30=0,,V30/T30) -> 0 | V30: =+T30*L30 -> 0
A31: =+A30+1 -> 12 | G31: =+E31*F31 -> 0 | J31: =+H31*I31 -> 0 | K31: =+E31+H31 -> 0 | L31: =IF(K31=0,,M31/K31) -> 0 | M31: =+J31+G31 -> 0 | O31: =+L31*N31 -> 0 | Q31: =+P31*L31 -> 0 | S31: =+R31*L31 -> 0 | T31: =+K31-N31-P31-R31 -> 0 | U31: =IF(T31=0,,V31/T31) -> 0 | V31: =+T31*L31 -> 0
A32: =+A31+1 -> 13 | G32: =+E32*F32 -> 0 | J32: =+H32*I32 -> 0 | K32: =+E32+H32 -> 0 | L32: =IF(K32=0,,M32/K32) -> 0 | M32: =+J32+G32 -> 0 | O32: =+L32*N32 -> 0 | Q32: =+P32*L32 -> 0 | S32: =+R32*L32 -> 0 | T32: =+K32-N32-P32-R32 -> 0 | U32: =IF(T32=0,,V32/T32) -> 0 | V32: =+T32*L32 -> 0
A33: =+A32+1 -> 14 | G33: =+E33*F33 -> 0 | J33: =+H33*I33 -> 0 | K33: =+E33+H33 -> 0 | L33: =IF(K33=0,,M33/K33) -> 0 | M33: =+J33+G33 -> 0 | O33: =+L33*N33 -> 0 | Q33: =+P33*L33 -> 0 | S33: =+R33*L33 -> 0 | T33: =+K33-N33-P33-R33 -> 0 | U33: =IF(T33=0,,V33/T33) -> 0 | V33: =+T33*L33 -> 0
... A37: =+A36+1 -> 18 | G37: =+E37*F37 -> 0 | J37: =+H37*I37 -> 0 | K37: =+E37+H37 -> 0 | L37: =IF(K37=0,,M37/K37) -> 0 | M37: =+J37+G37 -> 0 | O37: =+L37*N37 -> 0 | Q37: =+P37*L37 -> 0 | S37: =+R37*L37 -> 0 | T37: =+K37-N37-P37-R37 -> 0 | U37: =IF(T37=0,,V37/T37) -> 0 | V37: =+T37*L37 -> 0
B38: TOTAL BEER | D38: =+SUM(D20:D24) -> 96 | E38: =+SUM(E20:E24) -> 61 | G38: =+SUM(G20:G37) -> 34.21 | H38: =+SUM(H20:H37) -> 0 | J38: =+SUM(J20:J37) -> 0 | K38: =+SUM(K20:K37) -> 61 | M38: =+SUM(M20:M37) -> 34.21 | N38: =+SUM(N20:N37) -> 0 | O38: =+SUM(O20:O37) -> 0 | P38: =+SUM(P20:P37) -> 0 | Q38: =+SUM(Q20:Q37) -> 0 | R38: =+SUM(R20:R37) -> 0 | S38: =+SUM(S20:S37) -> 0 | T38: =+SUM(T20:T37) -> 61 | V38: =+SUM(V20:V37) -> 34.21
B39: Grand TOTAL | D39: =+SUM(D8:D38)/2 -> 480 | E39: =+SUM(E7:E38)/2 -> 180 | G39: =+SUM(G7:G38)/2 -> 70.065833 | H39: =+SUM(H7:H38)/2 -> 0 | J39: =+SUM(J7:J38)/2 -> 0 | K39: =+SUM(K7:K38)/2 -> 180 | M39: =+SUM(M7:M38)/2 -> 70.065833 | N39: =+SUM(N7:N38)/2 -> 0 | O39: =+SUM(O7:O38)/2 -> 0 | P39: =+SUM(P7:P38)/2 -> 0 | Q39: =+SUM(Q7:Q38)/2 -> 0 | R39: =+SUM(R7:R38)/2 -> 1 | S39: =+SUM(S7:S38)/2 -> 0.14833333 | T39: =+SUM(T7:T38)/2 -> 179 | V39: =+SUM(V7:V38)/2 -> 69.9175
A41: Prepared By: | H41: Checked By | R41: Acknowledge By:
A47: …........./……....../…........... | H47: …........./……....../…........... | R47: …........./……....../…...........

Sheet 02
A2: Stock Inventory Report of JULY 2026
S4: Date | T4: =+'01'!T4+1 -> 45840 | W4: Sale Report
A5: Nº | B5: Item Name | D5: Par Stock | E5: Opening | H5: Request | K5: In Stock | N5: Lost /Spoil | O5: Transfer out | P5: Cost of FOC | Q5: Cost of Sale | R5: Consumption | S5: Cost of Sale | T5: Closing
B6: English | C6: Khmer | E6: ដើមគ្រា | H6: បើកចូល | K6: ទំនិញមានក្នុងស្តុក | N6: ខូច/បាត់ | O6: ផ្ទេរចេញ | P6: ថ្លៃដើមព្រី | Q6: ថ្លៃដើមលក់ | R6: ថ្លៃដើមលក់ | S6: ថ្លៃដើមលក់ | T6: ចុងគ្រា | W6: Daily | AA6: Monthly
B7: ='01'!B7 -> Soft Drink | C7: ភេសជ្ជៈ | E7: Qtt | F7: U.P | G7: Amount | H7: Qtt | I7: U.P | J7: Amount | K7: Qtt | L7: U.P | M7: Amount | N7: Qtt | O7: Amount | P7: Qtt | Q7: Amount | R7: Qtt | S7: Amount | T7: Qtt | U7: U.P | V7: Amount | Y7: Qty | Z7: Amount | AA7: Qty | AB7: Amount
A8: 1 | B8: ='01'!B8 -> Cocacola Classic 330ml (24cans) | C8: ='01'!C8 -> កូកា ក្លាស៊ិក (កំប៉ុង៣៣០មម) | D8: ='01'!D8 -> 48 | E8: =+'01'!T8 -> 1 | F8: =+'01'!U8 -> 0.3625 | G8: =+'01'!V8 -> 0.3625 | J8: =+H8*I8 -> 0 | K8: =+E8+H8 -> 1 | L8: =IF(K8=0,,M8/K8) -> 0.3625 | M8: =+J8+G8 -> 0.3625 | O8: =+N8*L8 -> 0 | Q8: =+P8*L8 -> 0 | S8: =+R8*L8 -> 0 | T8: =+K8-N8-P8-R8 -> 1 | U8: =IF(T8=0,,V8/T8) -> 0.3625 | V8: =+T8*L8 -> 0.3625 | W8: =+$B$8 -> Cocacola Classic 330ml (24cans) | Y8: =+$R$8 -> 0 | Z8: =+Y8*1 -> 0 | AA8: =+Y8+'01'!AA8 -> 0 | AB8: =+Z8+'01'!AB8 -> 0
A9: =+A8+1 -> 2 | B9: ='01'!B9 -> Cocacola Zero 330ml (24cans) | C9: ='01'!C9 -> កូកា សេរ៉ូ (កំប៉ុង៣៣០មម) | D9: ='01'!D9 -> 48 | E9: =+'01'!T9 -> 18 | F9: =+'01'!U9 -> 0.3625 | G9: =+'01'!V9 -> 6.525 | J9: =+H9*I9 -> 0 | K9: =+E9+H9 -> 18 | L9: =IF(K9=0,,M9/K9) -> 0.3625 | M9: =+J9+G9 -> 6.525 | O9: =+N9*L9 -> 0 | Q9: =+P9*L9 -> 0 | S9: =+R9*L9 -> 0 | T9: =+K9-N9-P9-R9 -> 18 | U9: =IF(T9=0,,V9/T9) -> 0.3625 | V9: =+T9*L9 -> 6.525 | W9: =+$B$9 -> Cocacola Zero 330ml (24cans) | Y9: =+$R$9 -> 0 | Z9: =+Y9*1 -> 0 | AA9: =+Y9+'01'!AA9 -> 0 | AB9: =+Z9+'01'!AB9 -> 0
A10: =+A9+1 -> 3 | B10: ='01'!B10 -> Cocacola Light 330ml (24cans) | C10: ='01'!C10 -> កូកា ឡៃ (កំប៉ុង៣៣០មម) | D10: ='01'!D10 -> 48 | E10: =+'01'!T10 -> 11 | F10: =+'01'!U10 -> 0.3625 | G10: =+'01'!V10 -> 3.9875 | J10: =+H10*I10 -> 0 | K10: =+E10+H10 -> 11 | L10: =IF(K10=0,,M10/K10) -> 0.3625 | M10: =+J10+G10 -> 3.9875 | O10: =+N10*L10 -> 0 | Q10: =+P10*L10 -> 0 | S10: =+R10*L10 -> 0 | T10: =+K10-N10-P10-R10 -> 11 | U10: =IF(T10=0,,V10/T10) -> 0.3625 | V10: =+T10*L10 -> 3.9875 | W10: =+$B$10 -> Cocacola Light 330ml (24cans) | Y10: =+$R$10 -> 0 | Z10: =+Y10*1 -> 0 | AA10: =+Y10+'01'!AA10 -> 0 | AB10: =+Z10+'01'!AB10 -> 0
A11: =+A10+1 -> 4 | B11: ='01'!B11 -> Sprite 330ml (24cans) | C11: ='01'!C11 -> ស្ព្រៃ (កំប៉ុង៣៣០មម) | D11: ='01'!D11 -> 48 | E11: =+'01'!T11 -> 2 | F11: =+'01'!U11 -> 0.3625 | G11: =+'01'!V11 -> 0.725 | J11: =+H11*I11 -> 0 | K11: =+E11+H11 -> 2 | L11: =IF(K11=0,,M11/K11) -> 0.3625 | M11: =+J11+G11 -> 0.725 | O11: =+N11*L11 -> 0 | Q11: =+P11*L11 -> 0 | S11: =+R11*L11 -> 0 | T11: =+K11-N11-P11-R11 -> 2 | U11: =IF(T11=0,,V11/T11) -> 0.3625 | V11: =+T11*L11 -> 0.725 | W11: =+$B$11 -> Sprite 330ml (24cans) | Y11: =+$R$11 -> 0 | Z11: =+Y11*1 -> 0 | AA11: =+Y11+'01'!AA11 -> 0 | AB11: =+Z11+'01'!AB11 -> 0
A12: =+A11+1 -> 5 | B12: ='01'!B12 -> Schweppes Soda Water 330ml (24cans) | C12: ='01'!C12 -> ទឹកសូដា (កំប៉ុង៣៣០មម) | D12: ='01'!D12 -> 48 | E12: =+'01'!T12 -> 14 | F12: =+'01'!U12 -> 0.3625 | G12: =+'01'!V12 -> 5.075 | J12: =+H12*I12 -> 0 | K12: =+E12+H12 -> 14 | L12: =IF(K12=0,,M12/K12) -> 0.3625 | M12: =+J12+G12 -> 5.075 | O12: =+N12*L12 -> 0 | Q12: =+P12*L12 -> 0 | S12: =+R12*L12 -> 0 | T12: =+K12-N12-P12-R12 -> 14 | U12: =IF(T12=0,,V12/T12) -> 0.3625 | V12: =+T12*L12 -> 5.075 | W12: =+$B$12 -> Schweppes Soda Water 330ml (24cans) | Y12: =+$R$12 -> 0 | Z12: =+Y12*1 -> 0 | AA12: =+Y12+'01'!AA12 -> 0 | AB12: =+Z12+'01'!AB12 -> 0
A13: =+A12+1 -> 6 | B13: ='01'!B13 -> Schweppes Tonic Water 330ml (24cans) | C13: ='01'!C13 -> ទឹកតូនិច (កំប៉ុង៣៣០មម) | D13: ='01'!D13 -> 48 | E13: =+'01'!T13 -> 19 | F13: =+'01'!U13 -> 0.3625 | G13: =+'01'!V13 -> 6.8875 | J13: =+H13*I13 -> 0 | K13: =+E13+H13 -> 19 | L13: =IF(K13=0,,M13/K13) -> 0.3625 | M13: =+J13+G13 -> 6.8875 | O13: =+N13*L13 -> 0 | Q13: =+P13*L13 -> 0 | S13: =+R13*L13 -> 0 | T13: =+K13-N13-P13-R13 -> 19 | U13: =IF(T13=0,,V13/T13) -> 0.3625 | V13: =+T13*L13 -> 6.8875 | W13: =+$B$13 -> Schweppes Tonic Water 330ml (24cans) | Y13: =+$R$13 -> 0 | Z13: =+Y13*1 -> 0 | AA13: =+Y13+'01'!AA13 -> 0 | AB13: =+Z13+'01'!AB13 -> 0
A14: =+A13+1 -> 7 | B14: ='01'!B14 -> Schweppes Ginger Ale 330ml (24cans) | C14: ='01'!C14 -> ទឹក Ginger ale (កំប៉ុង៣៣០មម) | D14: ='01'!D14 -> 48 | E14: =+'01'!T14 -> 20 | F14: =+'01'!U14 -> 0.3625 | G14: =+'01'!V14 -> 7.25 | J14: =+H14*I14 -> 0 | K14: =+E14+H14 -> 20 | L14: =IF(K14=0,,M14/K14) -> 0.3625 | M14: =+J14+G14 -> 7.25 | O14: =+N14*L14 -> 0 | Q14: =+P14*L14 -> 0 | S14: =+R14*L14 -> 0 | T14: =+K14-N14-P14-R14 -> 20 | U14: =IF(T14=0,,V14/T14) -> 0.3625 | V14: =+T14*L14 -> 7.25 | W14: =+$B$14 -> Schweppes Ginger Ale 330ml (24cans) | Y14: =+$R$14 -> 0 | Z14: =+Y14*1 -> 0 | AA14: =+Y14+'01'!AA14 -> 0 | AB14: =+Z14+'01'!AB14 -> 0
B15: ='01'!B15 -> TOTAL SOFT DRINK | C15: ='01'!C15 -> 0 | D15: ='01'!D15 -> 336 | E15: =+SUM(E8:E14) -> 85 | G15: =+SUM(G8:G14) -> 30.8125 | H15: =+SUM(H8:H14) -> 0 | J15: =+SUM(J8:J14) -> 0 | K15: =+SUM(K8:K14) -> 85 | M15: =+SUM(M8:M14) -> 30.8125 | N15: =+SUM(N8:N14) -> 0 | O15: =+SUM(O8:O14) -> 0 | P15: =+SUM(P8:P14) -> 0 | Q15: =+SUM(Q8:Q14) -> 0 | R15: =+SUM(R8:R14) -> 0 | S15: =+SUM(S8:S14) -> 0 | T15: =+SUM(T8:T14) -> 85 | V15: =+SUM(V8:V14) -> 30.8125 | W15: =+$B$17 -> Dasani 500ml (24 Btl) | Y15: =+$R$17 -> 0 | Z15: =+Y15*0.5 -> 0 | AA15: =+Y15+'01'!AA15 -> 1 | AB15: =+Z15+'01'!AB15 -> 0.5
B16: ='01'!B16 -> Water | C16: ='01'!C16 -> 0 | D16: ='01'!D16 -> 0 | W16: =+$B$20 -> TIGER BEER 330ml CAN | Y16: =+$R$20 -> 0 | Z16: =+Y16*1.25 -> 0 | AA16: =+Y16+'01'!AA16 -> 0 | AB16: =+Z16+'01'!AB16 -> 0
A17: =+A14+1 -> 8 | B17: ='01'!B17 -> Dasani 500ml (24 Btl) | C17: ='01'!C17 -> 0 | D17: ='01'!D17 -> 48 | E17: =+'01'!T17 -> 33 | F17: =+'01'!U17 -> 0.14833333 | G17: =+'01'!V17 -> 4.895 | J17: =+H17*I17 -> 0 | K17: =+E17+H17 -> 33 | L17: =IF(K17=0,,M17/K17) -> 0.14833333 | M17: =+J17+G17 -> 4.895 | O17: =+N17*L17 -> 0 | Q17: =+P17*L17 -> 0 | S17: =+R17*L17 -> 0 | T17: =+K17-N17-P17-R17 -> 33 | U17: =IF(T17=0,,V17/T17) -> 0.14833333 | V17: =+T17*L17 -> 4.895 | W17: =+$B$21 -> Heineken 330ml CAN | Y17: =+$R$21 -> 0 | Z17: =+Y17*1.25 -> 0 | AA17: =+Y17+'01'!AA17 -> 0 | AB17: =+Z17+'01'!AB17 -> 0
B18: ='01'!B18 -> TOTAL Water | C18: ='01'!C18 -> 0 | D18: ='01'!D18 -> 48 | E18: =+E17 -> 33 | G18: =+G17 -> 4.895 | H18: =+H17 -> 0 | J18: =+J17 -> 0 | K18: =+K17 -> 33 | M18: =+M17 -> 4.895 | N18: =+N17 -> 0 | O18: =+O17 -> 0 | P18: =+P17 -> 0 | Q18: =+Q17 -> 0 | R18: =+R17 -> 0 | S18: =+S17 -> 0 | T18: =+T17 -> 33 | V18: =+V17 -> 4.895 | Y18: =+$R$22 -> 0 | Z18: =+Y18*1 -> 0 | AA18: =+Y18+'01'!AA18 -> 0 | AB18: =+Z18+'01'!AB18 -> 0
B19: ='01'!B19 -> Beer | C19: ='01'!C19 -> 0 | D19: ='01'!D19 -> 0 | Y19: =+$R$23 -> 0 | Z19: =+Y19*1 -> 0 | AA19: =+Y19+'01'!AA19 -> 0 | AB19: =+Z19+'01'!AB19 -> 0
A20: =+A19+1 -> 1 | B20: ='01'!B20 -> TIGER BEER 330ml CAN | C20: ='01'!C20 -> ស្រាបៀរថៃហ្គ័រ (កំប៉ុង ៣៣០មល) | D20: ='01'!D20 -> 48 | E20: =+'01'!T20 -> 32 | F20: =+'01'!U20 -> 0.48 | G20: =+'01'!V20 -> 15.36 | J20: =+H20*I20 -> 0 | K20: =+E20+H20 -> 32 | L20: =IF(K20=0,,M20/K20) -> 0.48 | M20: =+J20+G20 -> 15.36 | O20: =+N20*L20 -> 0 | Q20: =+P20*L20 -> 0 | S20: =+R20*L20 -> 0 | T20: =+K20-N20-P20-R20 -> 32 | U20: =IF(T20=0,,V20/T20) -> 0.48 | V20: =+T20*L20 -> 15.36 | W20: TOTAL | Y20: =+SUM(Y8:Y19) -> 0 | Z20: =+SUM(Z8:Z19) -> 0 | AA20: =+SUM(AA8:AA19) -> 1 | AB20: =+SUM(AB8:AB19) -> 0.5
A21: =+A20+1 -> 2 | B21: ='01'!B21 -> Heineken 330ml CAN | C21: ='01'!C21 -> ស្រាបៀរហេន័រឃិន (កំប៉ុង ៣៣០មល) | D21: ='01'!D21 -> 48 | E21: =+'01'!T21 -> 29 | F21: =+'01'!U21 -> 0.65 | G21: =+'01'!V21 -> 18.85 | J21: =+H21*I21 -> 0 | K21: =+E21+H21 -> 29 | L21: =IF(K21=0,,M21/K21) -> 0.65 | M21: =+J21+G21 -> 18.85 | O21: =+N21*L21 -> 0 | Q21: =+P21*L21 -> 0 | S21: =+R21*L21 -> 0 | T21: =+K21-N21-P21-R21 -> 29 | U21: =IF(T21=0,,V21/T21) -> 0.65 | V21: =+T21*L21 -> 18.85
A22: =+A21+1 -> 3 | B22: ='01'!B22 -> 0 | C22: ='01'!C22 -> 0 | D22: ='01'!D22 -> 0 | E22: =+'01'!T22 -> 0 | F22: =+'01'!U22 -> 0 | G22: =+'01'!V22 -> 0 | J22: =+H22*I22 -> 0 | K22: =+E22+H22 -> 0 | L22: =IF(K22=0,,M22/K22) -> 0 | M22: =+J22+G22 -> 0 | O22: =+N22*L22 -> 0 | Q22: =+P22*L22 -> 0 | S22: =+R22*L22 -> 0 | T22: =+K22-N22-P22-R22 -> 0 | U22: =IF(T22=0,,V22/T22) -> 0 | V22: =+T22*L22 -> 0
A23: =+A22+1 -> 4 | B23: ='01'!B23 -> 0 | C23: ='01'!C23 -> 0 | D23: ='01'!D23 -> 0 | E23: =+'01'!T23 -> 0 | F23: =+'01'!U23 -> 0 | G23: =+'01'!V23 -> 0 | J23: =+H23*I23 -> 0 | K23: =+E23+H23 -> 0 | L23: =IF(K23=0,,M23/K23) -> 0 | M23: =+J23+G23 -> 0 | O23: =+N23*L23 -> 0 | Q23: =+P23*L23 -> 0 | S23: =+R23*L23 -> 0 | T23: =+K23-N23-P23-R23 -> 0 | U23: =IF(T23=0,,V23/T23) -> 0 | V23: =+T23*L23 -> 0
A24: =+A23+1 -> 5 | B24: ='01'!B24 -> 0 | C24: ='01'!C24 -> 0 | D24: ='01'!D24 -> 0 | E24: =+'01'!T24 -> 0 | F24: =+'01'!U24 -> 0 | G24: =+'01'!V24 -> 0 | J24: =+H24*I24 -> 0 | K24: =+E24+H24 -> 0 | L24: =IF(K24=0,,M24/K24) -> 0 | M24: =+J24+G24 -> 0 | O24: =+N24*L24 -> 0 | Q24: =+P24*L24 -> 0 | S24: =+R24*L24 -> 0 | T24: =+K24-N24-P24-R24 -> 0 | U24: =IF(T24=0,,V24/T24) -> 0 | V24: =+T24*L24 -> 0
A25: =+A24+1 -> 6 | D25: ='01'!D25 -> 0 | E25: =+'01'!T25 -> 0 | F25: =+'01'!U25 -> 0 | G25: =+'01'!V25 -> 0 | J25: =+H25*I25 -> 0 | K25: =+E25+H25 -> 0 | L25: =IF(K25=0,,M25/K25) -> 0 | M25: =+J25+G25 -> 0 | O25: =+N25*L25 -> 0 | Q25: =+P25*L25 -> 0 | S25: =+R25*L25 -> 0 | T25: =+K25-N25-P25-R25 -> 0 | U25: =IF(T25=0,,V25/T25) -> 0 | V25: =+T25*L25 -> 0
A26: =+A25+1 -> 7 | D26: ='01'!D26 -> 0 | E26: =+'01'!T26 -> 0 | F26: =+'01'!U26 -> 0 | G26: =+'01'!V26 -> 0 | J26: =+H26*I26 -> 0 | K26: =+E26+H26 -> 0 | L26: =IF(K26=0,,M26/K26) -> 0 | M26: =+J26+G26 -> 0 | O26: =+N26*L26 -> 0 | Q26: =+P26*L26 -> 0 | S26: =+R26*L26 -> 0 | T26: =+K26-N26-P26-R26 -> 0 | U26: =IF(T26=0,,V26/T26) -> 0 | V26: =+T26*L26 -> 0
A27: =+A26+1 -> 8 | D27: ='01'!D27 -> 0 | E27: =+'01'!T27 -> 0 | F27: =+'01'!U27 -> 0 | G27: =+'01'!V27 -> 0 | J27: =+H27*I27 -> 0 | K27: =+E27+H27 -> 0 | L27: =IF(K27=0,,M27/K27) -> 0 | M27: =+J27+G27 -> 0 | O27: =+N27*L27 -> 0 | Q27: =+P27*L27 -> 0 | S27: =+R27*L27 -> 0 | T27: =+K27-N27-P27-R27 -> 0 | U27: =IF(T27=0,,V27/T27) -> 0 | V27: =+T27*L27 -> 0
A28: =+A27+1 -> 9 | D28: ='01'!D28 -> 0 | E28: =+'01'!T28 -> 0 | F28: =+'01'!U28 -> 0 | G28: =+'01'!V28 -> 0 | J28: =+H28*I28 -> 0 | K28: =+E28+H28 -> 0 | L28: =IF(K28=0,,M28/K28) -> 0 | M28: =+J28+G28 -> 0 | O28: =+N28*L28 -> 0 | Q28: =+P28*L28 -> 0 | S28: =+R28*L28 -> 0 | T28: =+K28-N28-P28-R28 -> 0 | U28: =IF(T28=0,,V28/T28) -> 0 | V28: =+T28*L28 -> 0
A29: =+A28+1 -> 10 | D29: ='01'!D29 -> 0 | E29: =+'01'!T29 -> 0 | F29: =+'01'!U29 -> 0 | G29: =+'01'!V29 -> 0 | J29: =+H29*I29 -> 0 | K29: =+E29+H29 -> 0 | L29: =IF(K29=0,,M29/K29) -> 0 | M29: =+J29+G29 -> 0 | O29: =+N29*L29 -> 0 | Q29: =+P29*L29 -> 0 | S29: =+R29*L29 -> 0 | T29: =+K29-N29-P29-R29 -> 0 | U29: =IF(T29=0,,V29/T29) -> 0 | V29: =+T29*L29 -> 0
A30: =+A29+1 -> 11 | D30: ='01'!D30 -> 0 | E30: =+'01'!T30 -> 0 | F30: =+'01'!U30 -> 0 | G30: =+'01'!V30 -> 0 | J30: =+H30*I30 -> 0 | K30: =+E30+H30 -> 0 | L30: =IF(K30=0,,M30/K30) -> 0 | M30: =+J30+G30 -> 0 | O30: =+N30*L30 -> 0 | Q30: =+P30*L30 -> 0 | S30: =+R30*L30 -> 0 | T30: =+K30-N30-P30-R30 -> 0 | U30: =IF(T30=0,,V30/T30) -> 0 | V30: =+T30*L30 -> 0
A31: =+A30+1 -> 12 | D31: ='01'!D31 -> 0 | E31: =+'01'!T31 -> 0 | F31: =+'01'!U31 -> 0 | G31: =+'01'!V31 -> 0 | J31: =+H31*I31 -> 0 | K31: =+E31+H31 -> 0 | L31: =IF(K31=0,,M31/K31) -> 0 | M31: =+J31+G31 -> 0 | O31: =+N31*L31 -> 0 | Q31: =+P31*L31 -> 0 | S31: =+R31*L31 -> 0 | T31: =+K31-N31-P31-R31 -> 0 | U31: =IF(T31=0,,V31/T31) -> 0 | V31: =+T31*L31 -> 0
A32: =+A31+1 -> 13 | D32: ='01'!D32 -> 0 | E32: =+'01'!T32 -> 0 | F32: =+'01'!U32 -> 0 | G32: =+'01'!V32 -> 0 | J32: =+H32*I32 -> 0 | K32: =+E32+H32 -> 0 | L32: =IF(K32=0,,M32/K32) -> 0 | M32: =+J32+G32 -> 0 | O32: =+N32*L32 -> 0 | Q32: =+P32*L32 -> 0 | S32: =+R32*L32 -> 0 | T32: =+K32-N32-P32-R32 -> 0 | U32: =IF(T32=0,,V32/T32) -> 0 | V32: =+T32*L32 -> 0
A33: =+A32+1 -> 14 | D33: ='01'!D33 -> 0 | E33: =+'01'!T33 -> 0 | F33: =+'01'!U33 -> 0 | G33: =+'01'!V33 -> 0 | J33: =+H33*I33 -> 0 | K33: =+E33+H33 -> 0 | L33: =IF(K33=0,,M33/K33) -> 0 | M33: =+J33+G33 -> 0 | O33: =+N33*L33 -> 0 | Q33: =+P33*L33 -> 0 | S33: =+R33*L33 -> 0 | T33: =+K33-N33-P33-R33 -> 0 | U33: =IF(T33=0,,V33/T33) -> 0 | V33: =+T33*L33 -> 0
A34: =+A33+1 -> 15 | D34: ='01'!D34 -> 0 | E34: =+'01'!T34 -> 0 | F34: =+'01'!U34 -> 0 | G34: =+'01'!V34 -> 0 | J34: =+H34*I34 -> 0 | K34: =+E34+H34 -> 0 | L34: =IF(K34=0,,M34/K34) -> 0 | M34: =+J34+G34 -> 0 | O34: =+N34*L34 -> 0 | Q34: =+P34*L34 -> 0 | S34: =+R34*L34 -> 0 | T34: =+K34-N34-P34-R34 -> 0 | U34: =IF(T34=0,,V34/T34) -> 0 | V34: =+T34*L34 -> 0
A35: =+A34+1 -> 16 | D35: ='01'!D35 -> 0 | E35: =+'01'!T35 -> 0 | F35: =+'01'!U35 -> 0 | G35: =+'01'!V35 -> 0 | J35: =+H35*I35 -> 0 | K35: =+E35+H35 -> 0 | L35: =IF(K35=0,,M35/K35) -> 0 | M35: =+J35+G35 -> 0 | O35: =+N35*L35 -> 0 | Q35: =+P35*L35 -> 0 | S35: =+R35*L35 -> 0 | T35: =+K35-N35-P35-R35 -> 0 | U35: =IF(T35=0,,V35/T35) -> 0 | V35: =+T35*L35 -> 0
A36: =+A35+1 -> 17 | D36: ='01'!D36 -> 0 | E36: =+'01'!T36 -> 0 | F36: =+'01'!U36 -> 0 | G36: =+'01'!V36 -> 0 | J36: =+H36*I36 -> 0 | K36: =+E36+H36 -> 0 | L36: =IF(K36=0,,M36/K36) -> 0 | M36: =+J36+G36 -> 0 | O36: =+N36*L36 -> 0 | Q36: =+P36*L36 -> 0 | S36: =+R36*L36 -> 0 | T36: =+K36-N36-P36-R36 -> 0 | U36: =IF(T36=0,,V36/T36) -> 0 | V36: =+T36*L36 -> 0
A37: =+A36+1 -> 18 | D37: ='01'!D37 -> 0 | E37: =+'01'!T37 -> 0 | F37: =+'01'!U37 -> 0 | G37: =+'01'!V37 -> 0 | J37: =+H37*I37 -> 0 | K37: =+E37+H37 -> 0 | L37: =IF(K37=0,,M37/K37) -> 0 | M37: =+J37+G37 -> 0 | O37: =+N37*L37 -> 0 | Q37: =+P37*L37 -> 0 | S37: =+R37*L37 -> 0 | T37: =+K37-N37-P37-R37 -> 0 | U37: =IF(T37=0,,V37/T37) -> 0 | V37: =+T37*L37 -> 0
B38: ='01'!B38 -> TOTAL BEER | C38: ='01'!C38 -> 0 | D38: ='01'!D38 -> 96 | E38: =+SUM(E20:E24) -> 61 | G38: =+SUM(G20:G37) -> 34.21 | H38: =+SUM(H20:H37) -> 0 | J38: =+SUM(J20:J37) -> 0 | K38: =+SUM(K20:K37) -> 61 | M38: =+SUM(M20:M37) -> 34.21 | N38: =+SUM(N20:N37) -> 0 | O38: =+SUM(O20:O37) -> 0 | P38: =+SUM(P20:P37) -> 0 | Q38: =+SUM(Q20:Q37) -> 0 | R38: =+SUM(R20:R37) -> 0 | S38: =+SUM(S20:S37) -> 0 | T38: =+SUM(T20:T37) -> 61 | V38: =+SUM(V20:V37) -> 34.21
B39: ='01'!B39 -> Grand TOTAL | C39: ='01'!C39 -> 0 | D39: ='01'!D39 -> 480 | E39: =+SUM(E7:E38)/2 -> 179 | G39: =+SUM(G7:G38)/2 -> 69.9175 | H39: =+SUM(H7:H38)/2 -> 0 | J39: =+SUM(J7:J38)/2 -> 0 | K39: =+SUM(K7:K38)/2 -> 179 | M39: =+SUM(M7:M38)/2 -> 69.9175 | N39: =+SUM(N7:N38)/2 -> 0 | O39: =+SUM(O7:O38)/2 -> 0 | P39: =+SUM(P7:P38)/2 -> 0 | Q39: =+SUM(Q7:Q38)/2 -> 0 | R39: =+SUM(R7:R38)/2 -> 0 | S39: =+SUM(S7:S38)/2 -> 0 | T39: =+SUM(T7:T38)/2 -> 179 | V39: =+SUM(V7:V38)/2 -> 69.9175
A41: Prepared By: | H41: Checked By | R41: Acknowledge By:
A47: …........./……....../…........... | H47: …........./……....../…........... | R47: …........./……....../…...........

Sheet 03
A2: Stock Inventory Report of JULY 2026
S4: Date | T4: =+'02'!T4+1 -> 45841 | W4: Sale Report
A5: Nº | B5: Item Name | D5: Par Stock | E5: Opening | H5: Request | K5: In Stock | N5: Lost /Spoil | O5: Transfer out | P5: Cost of FOC | Q5: Cost of Sale | R5: Consumption | S5: Cost of Sale | T5: Closing
B6: English | C6: Khmer | E6: ដើមគ្រា | H6: បើកចូល | K6: ទំនិញមានក្នុងស្តុក | N6: ខូច/បាត់ | O6: ផ្ទេរចេញ | P6: ថ្លៃដើមព្រី | Q6: ថ្លៃដើមលក់ | R6: ថ្លៃដើមលក់ | S6: ថ្លៃដើមលក់ | T6: ចុងគ្រា | X6: Daily | AB6: Monthly
B7: ='01'!B7 -> Soft Drink | C7: ភេសជ្ជៈ | E7: Qtt | F7: U.P | G7: Amount | H7: Qtt | I7: U.P | J7: Amount | K7: Qtt | L7: U.P | M7: Amount | N7: Qtt | O7: Amount | P7: Qtt | Q7: Amount | R7: Qtt | S7: Amount | T7: Qtt | U7: U.P | V7: Amount | Z7: Qty | AA7: Amount | AB7: Qty | AC7: Amount
A8: 1 | B8: ='01'!B8 -> Cocacola Classic 330ml (24cans) | C8: ='01'!C8 -> កូកា ក្លាស៊ិក (កំប៉ុង៣៣០មម) | D8: ='01'!D8 -> 48 | E8: =+'02'!T8 -> 1 | F8: =+'02'!U8 -> 0.3625 | G8: =+'02'!V8 -> 0.3625 | J8: =+H8*I8 -> 0 | K8: =+E8+H8 -> 1 | L8: =IF(K8=0,,M8/K8) -> 0.3625 | M8: =+J8+G8 -> 0.3625 | O8: =+N8*L8 -> 0 | Q8: =+P8*L8 -> 0 | S8: =+R8*L8 -> 0 | T8: =+K8-N8-P8-R8 -> 1 | U8: =IF(T8=0,,V8/T8) -> 0.3625 | V8: =+T8*L8 -> 0.3625 | X8: =+$B$8 -> Cocacola Classic 330ml (24cans) | Z8: =+$R$8 -> 0 | AA8: =+Z8*1 -> 0 | AB8: =+Z8+'02'!AA8 -> 0 | AC8: =+AA8+'02'!AB8 -> 0
A9: =+A8+1 -> 2 | B9: ='01'!B9 -> Cocacola Zero 330ml (24cans) | C9: ='01'!C9 -> កូកា សេរ៉ូ (កំប៉ុង៣៣០មម) | D9: ='01'!D9 -> 48 | E9: =+'02'!T9 -> 18 | F9: =+'02'!U9 -> 0.3625 | G9: =+'02'!V9 -> 6.525 | J9: =+H9*I9 -> 0 | K9: =+E9+H9 -> 18 | L9: =IF(K9=0,,M9/K9) -> 0.3625 | M9: =+J9+G9 -> 6.525 | O9: =+N9*L9 -> 0 | Q9: =+P9*L9 -> 0 | S9: =+R9*L9 -> 0 | T9: =+K9-N9-P9-R9 -> 18 | U9: =IF(T9=0,,V9/T9) -> 0.3625 | V9: =+T9*L9 -> 6.525 | X9: =+$B$9 -> Cocacola Zero 330ml (24cans) | Z9: =+$R$9 -> 0 | AA9: =+Z9*1 -> 0 | AB9: =+Z9+'02'!AA9 -> 0 | AC9: =+AA9+'02'!AB9 -> 0
A10: =+A9+1 -> 3 | B10: ='01'!B10 -> Cocacola Light 330ml (24cans) | C10: ='01'!C10 -> កូកា ឡៃ (កំប៉ុង៣៣០មម) | D10: ='01'!D10 -> 48 | E10: =+'02'!T10 -> 11 | F10: =+'02'!U10 -> 0.3625 | G10: =+'02'!V10 -> 3.9875 | J10: =+H10*I10 -> 0 | K10: =+E10+H10 -> 11 | L10: =IF(K10=0,,M10/K10) -> 0.3625 | M10: =+J10+G10 -> 3.9875 | O10: =+N10*L10 -> 0 | Q10: =+P10*L10 -> 0 | S10: =+R10*L10 -> 0 | T10: =+K10-N10-P10-R10 -> 11 | U10: =IF(T10=0,,V10/T10) -> 0.3625 | V10: =+T10*L10 -> 3.9875 | X10: =+$B$10 -> Cocacola Light 330ml (24cans) | Z10: =+$R$10 -> 0 | AA10: =+Z10*1 -> 0 | AB10: =+Z10+'02'!AA10 -> 0 | AC10: =+AA10+'02'!AB10 -> 0
A11: =+A10+1 -> 4 | B11: ='01'!B11 -> Sprite 330ml (24cans) | C11: ='01'!C11 -> ស្ព្រៃ (កំប៉ុង៣៣០មម) | D11: ='01'!D11 -> 48 | E11: =+'02'!T11 -> 2 | F11: =+'02'!U11 -> 0.3625 | G11: =+'02'!V11 -> 0.725 | J11: =+H11*I11 -> 0 | K11: =+E11+H11 -> 2 | L11: =IF(K11=0,,M11/K11) -> 0.3625 | M11: =+J11+G11 -> 0.725 | O11: =+N11*L11 -> 0 | Q11: =+P11*L11 -> 0 | S11: =+R11*L11 -> 0 | T11: =+K11-N11-P11-R11 -> 2 | U11: =IF(T11=0,,V11/T11) -> 0.3625 | V11: =+T11*L11 -> 0.725 | X11: =+$B$11 -> Sprite 330ml (24cans) | Z11: =+$R$11 -> 0 | AA11: =+Z11*1 -> 0 | AB11: =+Z11+'02'!AA11 -> 0 | AC11: =+AA11+'02'!AB11 -> 0
A12: =+A11+1 -> 5 | B12: ='01'!B12 -> Schweppes Soda Water 330ml (24cans) | C12: ='01'!C12 -> ទឹកសូដា (កំប៉ុង៣៣០មម) | D12: ='01'!D12 -> 48 | E12: =+'02'!T12 -> 14 | F12: =+'02'!U12 -> 0.3625 | G12: =+'02'!V12 -> 5.075 | J12: =+H12*I12 -> 0 | K12: =+E12+H12 -> 14 | L12: =IF(K12=0,,M12/K12) -> 0.3625 | M12: =+J12+G12 -> 5.075 | O12: =+N12*L12 -> 0 | Q12: =+P12*L12 -> 0 | S12: =+R12*L12 -> 0 | T12: =+K12-N12-P12-R12 -> 14 | U12: =IF(T12=0,,V12/T12) -> 0.3625 | V12: =+T12*L12 -> 5.075 | X12: =+$B$12 -> Schweppes Soda Water 330ml (24cans) | Z12: =+$R$12 -> 0 | AA12: =+Z12*1 -> 0 | AB12: =+Z12+'02'!AA12 -> 0 | AC12: =+AA12+'02'!AB12 -> 0
A13: =+A12+1 -> 6 | B13: ='01'!B13 -> Schweppes Tonic Water 330ml (24cans) | C13: ='01'!C13 -> ទឹកតូនិច (កំប៉ុង៣៣០មម) | D13: ='01'!D13 -> 48 | E13: =+'02'!T13 -> 19 | F13: =+'02'!U13 -> 0.3625 | G13: =+'02'!V13 -> 6.8875 | J13: =+H13*I13 -> 0 | K13: =+E13+H13 -> 19 | L13: =IF(K13=0,,M13/K13) -> 0.3625 | M13: =+J13+G13 -> 6.8875 | O13: =+N13*L13 -> 0 | Q13: =+P13*L13 -> 0 | S13: =+R13*L13 -> 0 | T13: =+K13-N13-P13-R13 -> 19 | U13: =IF(T13=0,,V13/T13) -> 0.3625 | V13: =+T13*L13 -> 6.8875 | X13: =+$B$13 -> Schweppes Tonic Water 330ml (24cans) | Z13: =+$R$13 -> 0 | AA13: =+Z13*1 -> 0 | AB13: =+Z13+'02'!AA13 -> 0 | AC13: =+AA13+'02'!AB13 -> 0
A14: =+A13+1 -> 7 | B14: ='01'!B14 -> Schweppes Ginger Ale 330ml (24cans) | C14: ='01'!C14 -> ទឹក Ginger ale (កំប៉ុង៣៣០មម) | D14: ='01'!D14 -> 48 | E14: =+'02'!T14 -> 20 | F14: =+'02'!U14 -> 0.3625 | G14: =+'02'!V14 -> 7.25 | J14: =+H14*I14 -> 0 | K14: =+E14+H14 -> 20 | L14: =IF(K14=0,,M14/K14) -> 0.3625 | M14: =+J14+G14 -> 7.25 | O14: =+N14*L14 -> 0 | Q14: =+P14*L14 -> 0 | S14: =+R14*L14 -> 0 | T14: =+K14-N14-P14-R14 -> 20 | U14: =IF(T14=0,,V14/T14) -> 0.3625 | V14: =+T14*L14 -> 7.25 | X14: =+$B$14 -> Schweppes Ginger Ale 330ml (24cans) | Z14: =+$R$14 -> 0 | AA14: =+Z14*1 -> 0 | AB14: =+Z14+'02'!AA14 -> 0 | AC14: =+AA14+'02'!AB14 -> 0
B15: ='01'!B15 -> TOTAL SOFT DRINK | C15: ='01'!C15 -> 0 | D15: ='01'!D15 -> 336 | E15: =+SUM(E8:E14) -> 85 | G15: =+SUM(G8:G14) -> 30.8125 | H15: =+SUM(H8:H14) -> 0 | J15: =+SUM(J8:J14) -> 0 | K15: =+SUM(K8:K14) -> 85 | M15: =+SUM(M8:M14) -> 30.8125 | N15: =+SUM(N8:N14) -> 0 | O15: =+SUM(O8:O14) -> 0 | P15: =+SUM(P8:P14) -> 0 | Q15: =+SUM(Q8:Q14) -> 0 | R15: =+SUM(R8:R14) -> 0 | S15: =+SUM(S8:S14) -> 0 | T15: =+SUM(T8:T14) -> 85 | V15: =+SUM(V8:V14) -> 30.8125 | X15: =+$B$17 -> Dasani 500ml (24 Btl) | Z15: =+$R$17 -> 4 | AA15: =+Z15*0.5 -> 2 | AB15: =+Z15+'02'!AA15 -> 5 | AC15: =+AA15+'02'!AB15 -> 2.5
B16: ='01'!B16 -> Water | C16: ='01'!C16 -> 0 | D16: ='01'!D16 -> 0 | X16: =+$B$20 -> TIGER BEER 330ml CAN | Z16: =+$R$20 -> 0 | AA16: =+Z16*1.25 -> 0 | AB16: =+Z16+'02'!AA16 -> 0 | AC16: =+AA16+'02'!AB16 -> 0
A17: =+A14+1 -> 8 | B17: ='01'!B17 -> Dasani 500ml (24 Btl) | C17: ='01'!C17 -> 0 | D17: ='01'!D17 -> 48 | E17: =+'02'!T17 -> 33 | F17: =+'02'!U17 -> 0.14833333 | G17: =+'02'!V17 -> 4.895 | J17: =+H17*I17 -> 0 | K17: =+E17+H17 -> 33 | L17: =IF(K17=0,,M17/K17) -> 0.14833333 | M17: =+J17+G17 -> 4.895 | O17: =+N17*L17 -> 0 | Q17: =+P17*L17 -> 0 | R17: 4 | S17: =+R17*L17 -> 0.59333333 | T17: =+K17-N17-P17-R17 -> 29 | U17: =IF(T17=0,,V17/T17) -> 0.14833333 | V17: =+T17*L17 -> 4.3016667 | X17: =+$B$21 -> Heineken 330ml CAN | Z17: =+$R$21 -> 0 | AA17: =+Z17*1.25 -> 0 | AB17: =+Z17+'02'!AA17 -> 0 | AC17: =+AA17+'02'!AB17 -> 0
B18: ='01'!B18 -> TOTAL Water | C18: ='01'!C18 -> 0 | D18: ='01'!D18 -> 48 | E18: =+E17 -> 33 | G18: =+G17 -> 4.895 | H18: =+H17 -> 0 | J18: =+J17 -> 0 | K18: =+K17 -> 33 | M18: =+M17 -> 4.895 | N18: =+N17 -> 0 | O18: =+O17 -> 0 | P18: =+P17 -> 0 | Q18: =+Q17 -> 0 | R18: =+R17 -> 4 | S18: =+S17 -> 0.59333333 | T18: =+T17 -> 29 | V18: =+V17 -> 4.3016667 | Z18: =+$R$22 -> 0 | AA18: =+Z18*1 -> 0 | AB18: =+Z18+'02'!AA18 -> 0 | AC18: =+AA18+'02'!AB18 -> 0
B19: ='01'!B19 -> Beer | C19: ='01'!C19 -> 0 | D19: ='01'!D19 -> 0 | Z19: =+$R$23 -> 0 | AA19: =+Z19*1 -> 0 | AB19: =+Z19+'02'!AA19 -> 0 | AC19: =+AA19+'02'!AB19 -> 0
A20: =+A19+1 -> 1 | B20: ='01'!B20 -> TIGER BEER 330ml CAN | C20: ='01'!C20 -> ស្រាបៀរថៃហ្គ័រ (កំប៉ុង ៣៣០មល) | D20: ='01'!D20 -> 48 | E20: =+'02'!T20 -> 32 | F20: =+'02'!U20 -> 0.48 | G20: =+'02'!V20 -> 15.36 | J20: =+H20*I20 -> 0 | K20: =+E20+H20 -> 32 | L20: =IF(K20=0,,M20/K20) -> 0.48 | M20: =+J20+G20 -> 15.36 | O20: =+N20*L20 -> 0 | Q20: =+P20*L20 -> 0 | S20: =+R20*L20 -> 0 | T20: =+K20-N20-P20-R20 -> 32 | U20: =IF(T20=0,,V20/T20) -> 0.48 | V20: =+T20*L20 -> 15.36 | X20: TOTAL | Z20: =+SUM(Z8:Z19) -> 4 | AA20: =+SUM(AA8:AA19) -> 2 | AB20: =+SUM(AB8:AB19) -> 5 | AC20: =+SUM(AC8:AC19) -> 2.5
A21: =+A20+1 -> 2 | B21: ='01'!B21 -> Heineken 330ml CAN | C21: ='01'!C21 -> ស្រាបៀរហេន័រឃិន (កំប៉ុង ៣៣០មល) | D21: ='01'!D21 -> 48 | E21: =+'02'!T21 -> 29 | F21: =+'02'!U21 -> 0.65 | G21: =+'02'!V21 -> 18.85 | J21: =+H21*I21 -> 0 | K21: =+E21+H21 -> 29 | L21: =IF(K21=0,,M21/K21) -> 0.65 | M21: =+J21+G21 -> 18.85 | O21: =+N21*L21 -> 0 | Q21: =+P21*L21 -> 0 | S21: =+R21*L21 -> 0 | T21: =+K21-N21-P21-R21 -> 29 | U21: =IF(T21=0,,V21/T21) -> 0.65 | V21: =+T21*L21 -> 18.85
A22: =+A21+1 -> 3 | B22: ='01'!B22 -> 0 | C22: ='01'!C22 -> 0 | D22: ='01'!D22 -> 0 | E22: =+'02'!T22 -> 0 | F22: =+'02'!U22 -> 0 | G22: =+'02'!V22 -> 0 | J22: =+H22*I22 -> 0 | K22: =+E22+H22 -> 0 | L22: =IF(K22=0,,M22/K22) -> 0 | M22: =+J22+G22 -> 0 | O22: =+N22*L22 -> 0 | Q22: =+P22*L22 -> 0 | S22: =+R22*L22 -> 0 | T22: =+K22-N22-P22-R22 -> 0 | U22: =IF(T22=0,,V22/T22) -> 0 | V22: =+T22*L22 -> 0
A23: =+A22+1 -> 4 | B23: ='01'!B23 -> 0 | C23: ='01'!C23 -> 0 | D23: ='01'!D23 -> 0 | E23: =+'02'!T23 -> 0 | F23: =+'02'!U23 -> 0 | G23: =+'02'!V23 -> 0 | J23: =+H23*I23 -> 0 | K23: =+E23+H23 -> 0 | L23: =IF(K23=0,,M23/K23) -> 0 | M23: =+J23+G23 -> 0 | O23: =+N23*L23 -> 0 | Q23: =+P23*L23 -> 0 | S23: =+R23*L23 -> 0 | T23: =+K23-N23-P23-R23 -> 0 | U23: =IF(T23=0,,V23/T23) -> 0 | V23: =+T23*L23 -> 0
A24: =+A23+1 -> 5 | B24: ='01'!B24 -> 0 | C24: ='01'!C24 -> 0 | D24: ='01'!D24 -> 0 | E24: =+'02'!T24 -> 0 | F24: =+'02'!U24 -> 0 | G24: =+'02'!V24 -> 0 | J24: =+H24*I24 -> 0 | K24: =+E24+H24 -> 0 | L24: =IF(K24=0,,M24/K24) -> 0 | M24: =+J24+G24 -> 0 | O24: =+N24*L24 -> 0 | Q24: =+P24*L24 -> 0 | S24: =+R24*L24 -> 0 | T24: =+K24-N24-P24-R24 -> 0 | U24: =IF(T24=0,,V24/T24) -> 0 | V24: =+T24*L24 -> 0
A25: =+A24+1 -> 6 | D25: ='01'!D25 -> 0 | E25: =+'02'!T25 -> 0 | F25: =+'02'!U25 -> 0 | G25: =+'02'!V25 -> 0 | J25: =+H25*I25 -> 0 | K25: =+E25+H25 -> 0 | L25: =IF(K25=0,,M25/K25) -> 0 | M25: =+J25+G25 -> 0 | O25: =+N25*L25 -> 0 | Q25: =+P25*L25 -> 0 | S25: =+R25*L25 -> 0 | T25: =+K25-N25-P25-R25 -> 0 | U25: =IF(T25=0,,V25/T25) -> 0 | V25: =+T25*L25 -> 0
A26: =+A25+1 -> 7 | D26: ='01'!D26 -> 0 | E26: =+'02'!T26 -> 0 | F26: =+'02'!U26 -> 0 | G26: =+'02'!V26 -> 0 | J26: =+H26*I26 -> 0 | K26: =+E26+H26 -> 0 | L26: =IF(K26=0,,M26/K26) -> 0 | M26: =+J26+G26 -> 0 | O26: =+N26*L26 -> 0 | Q26: =+P26*L26 -> 0 | S26: =+R26*L26 -> 0 | T26: =+K26-N26-P26-R26 -> 0 | U26: =IF(T26=0,,V26/T26) -> 0 | V26: =+T26*L26 -> 0
A27: =+A26+1 -> 8 | D27: ='01'!D27 -> 0 | E27: =+'02'!T27 -> 0 | F27: =+'02'!U27 -> 0 | G27: =+'02'!V27 -> 0 | J27: =+H27*I27 -> 0 | K27: =+E27+H27 -> 0 | L27: =IF(K27=0,,M27/K27) -> 0 | M27: =+J27+G27 -> 0 | O27: =+N27*L27 -> 0 | Q27: =+P27*L27 -> 0 | S27: =+R27*L27 -> 0 | T27: =+K27-N27-P27-R27 -> 0 | U27: =IF(T27=0,,V27/T27) -> 0 | V27: =+T27*L27 -> 0
A28: =+A27+1 -> 9 | D28: ='01'!D28 -> 0 | E28: =+'02'!T28 -> 0 | F28: =+'02'!U28 -> 0 | G28: =+'02'!V28 -> 0 | J28: =+H28*I28 -> 0 | K28: =+E28+H28 -> 0 | L28: =IF(K28=0,,M28/K28) -> 0 | M28: =+J28+G28 -> 0 | O28: =+N28*L28 -> 0 | Q28: =+P28*L28 -> 0 | S28: =+R28*L28 -> 0 | T28: =+K28-N28-P28-R28 -> 0 | U28: =IF(T28=0,,V28/T28) -> 0 | V28: =+T28*L28 -> 0
A29: =+A28+1 -> 10 | D29: ='01'!D29 -> 0 | E29: =+'02'!T29 -> 0 | F29: =+'02'!U29 -> 0 | G29: =+'02'!V29 -> 0 | J29: =+H29*I29 -> 0 | K29: =+E29+H29 -> 0 | L29: =IF(K29=0,,M29/K29) -> 0 | M29: =+J29+G29 -> 0 | O29: =+N29*L29 -> 0 | Q29: =+P29*L29 -> 0 | S29: =+R29*L29 -> 0 | T29: =+K29-N29-P29-R29 -> 0 | U29: =IF(T29=0,,V29/T29) -> 0 | V29: =+T29*L29 -> 0
A30: =+A29+1 -> 11 | D30: ='01'!D30 -> 0 | E30: =+'02'!T30 -> 0 | F30: =+'02'!U30 -> 0 | G30: =+'02'!V30 -> 0 | J30: =+H30*I30 -> 0 | K30: =+E30+H30 -> 0 | L30: =IF(K30=0,,M30/K30) -> 0 | M30: =+J30+G30 -> 0 | O30: =+N30*L30 -> 0 | Q30: =+P30*L30 -> 0 | S30: =+R30*L30 -> 0 | T30: =+K30-N30-P30-R30 -> 0 | U30: =IF(T30=0,,V30/T30) -> 0 | V30: =+T30*L30 -> 0
A31: =+A30+1 -> 12 | D31: ='01'!D31 -> 0 | E31: =+'02'!T31 -> 0 | F31: =+'02'!U31 -> 0 | G31: =+'02'!V31 -> 0 | J31: =+H31*I31 -> 0 | K31: =+E31+H31 -> 0 | L31: =IF(K31=0,,M31/K31) -> 0 | M31: =+J31+G31 -> 0 | O31: =+N31*L31 -> 0 | Q31: =+P31*L31 -> 0 | S31: =+R31*L31 -> 0 | T31: =+K31-N31-P31-R31 -> 0 | U31: =IF(T31=0,,V31/T31) -> 0 | V31: =+T31*L31 -> 0
A32: =+A31+1 -> 13 | D32: ='01'!D32 -> 0 | E32: =+'02'!T32 -> 0 | F32: =+'02'!U32 -> 0 | G32: =+'02'!V32 -> 0 | J32: =+H32*I32 -> 0 | K32: =+E32+H32 -> 0 | L32: =IF(K32=0,,M32/K32) -> 0 | M32: =+J32+G32 -> 0 | O32: =+N32*L32 -> 0 | Q32: =+P32*L32 -> 0 | S32: =+R32*L32 -> 0 | T32: =+K32-N32-P32-R32 -> 0 | U32: =IF(T32=0,,V32/T32) -> 0 | V32: =+T32*L32 -> 0
A33: =+A32+1 -> 14 | D33: ='01'!D33 -> 0 | E33: =+'02'!T33 -> 0 | F33: =+'02'!U33 -> 0 | G33: =+'02'!V33 -> 0 | J33: =+H33*I33 -> 0 | K33: =+E33+H33 -> 0 | L33: =IF(K33=0,,M33/K33) -> 0 | M33: =+J33+G33 -> 0 | O33: =+N33*L33 -> 0 | Q33: =+P33*L33 -> 0 | S33: =+R33*L33 -> 0 | T33: =+K33-N33-P33-R33 -> 0 | U33: =IF(T33=0,,V33/T33) -> 0 | V33: =+T33*L33 -> 0
A34: =+A33+1 -> 15 | D34: ='01'!D34 -> 0 | E34: =+'02'!T34 -> 0 | F34: =+'02'!U34 -> 0 | G34: =+'02'!V34 -> 0 | J34: =+H34*I34 -> 0 | K34: =+E34+H34 -> 0 | L34: =IF(K34=0,,M34/K34) -> 0 | M34: =+J34+G34 -> 0 | O34: =+N34*L34 -> 0 | Q34: =+P34*L34 -> 0 | S34: =+R34*L34 -> 0 | T34: =+K34-N34-P34-R34 -> 0 | U34: =IF(T34=0,,V34/T34) -> 0 | V34: =+T34*L34 -> 0
A35: =+A34+1 -> 16 | D35: ='01'!D35 -> 0 | E35: =+'02'!T35 -> 0 | F35: =+'02'!U35 -> 0 | G35: =+'02'!V35 -> 0 | J35: =+H35*I35 -> 0 | K35: =+E35+H35 -> 0 | L35: =IF(K35=0,,M35/K35) -> 0 | M35: =+J35+G35 -> 0 | O35: =+N35*L35 -> 0 | Q35: =+P35*L35 -> 0 | S35: =+R35*L35 -> 0 | T35: =+K35-N35-P35-R35 -> 0 | U35: =IF(T35=0,,V35/T35) -> 0 | V35: =+T35*L35 -> 0
A36: =+A35+1 -> 17 | D36: ='01'!D36 -> 0 | E36: =+'02'!T36 -> 0 | F36: =+'02'!U36 -> 0 | G36: =+'02'!V36 -> 0 | J36: =+H36*I36 -> 0 | K36: =+E36+H36 -> 0 | L36: =IF(K36=0,,M36/K36) -> 0 | M36: =+J36+G36 -> 0 | O36: =+N36*L36 -> 0 | Q36: =+P36*L36 -> 0 | S36: =+R36*L36 -> 0 | T36: =+K36-N36-P36-R36 -> 0 | U36: =IF(T36=0,,V36/T36) -> 0 | V36: =+T36*L36 -> 0
A37: =+A36+1 -> 18 | D37: ='01'!D37 -> 0 | E37: =+'02'!T37 -> 0 | F37: =+'02'!U37 -> 0 | G37: =+'02'!V37 -> 0 | J37: =+H37*I37 -> 0 | K37: =+E37+H37 -> 0 | L37: =IF(K37=0,,M37/K37) -> 0 | M37: =+J37+G37 -> 0 | O37: =+N37*L37 -> 0 | Q37: =+P37*L37 -> 0 | S37: =+R37*L37 -> 0 | T37: =+K37-N37-P37-R37 -> 0 | U37: =IF(T37=0,,V37/T37) -> 0 | V37: =+T37*L37 -> 0
B38: ='01'!B38 -> TOTAL BEER | C38: ='01'!C38 -> 0 | D38: ='01'!D38 -> 96 | E38: =+SUM(E20:E24) -> 61 | G38: =+SUM(G20:G37) -> 34.21 | H38: =+SUM(H20:H37) -> 0 | J38: =+SUM(J20:J37) -> 0 | K38: =+SUM(K20:K37) -> 61 | M38: =+SUM(M20:M37) -> 34.21 | N38: =+SUM(N20:N37) -> 0 | O38: =+SUM(O20:O37) -> 0 | P38: =+SUM(P20:P37) -> 0 | Q38: =+SUM(Q20:Q37) -> 0 | R38: =+SUM(R20:R37) -> 0 | S38: =+SUM(S20:S37) -> 0 | T38: =+SUM(T20:T37) -> 61 | V38: =+SUM(V20:V37) -> 34.21
B39: ='01'!B39 -> Grand TOTAL | C39: ='01'!C39 -> 0 | D39: ='01'!D39 -> 480 | E39: =+SUM(E7:E38)/2 -> 179 | G39: =+SUM(G7:G38)/2 -> 69.9175 | H39: =+SUM(H7:H38)/2 -> 0 | J39: =+SUM(J7:J38)/2 -> 0 | K39: =+SUM(K7:K38)/2 -> 179 | M39: =+SUM(M7:M38)/2 -> 69.9175 | N39: =+SUM(N7:N38)/2 -> 0 | O39: =+SUM(O7:O38)/2 -> 0 | P39: =+SUM(P7:P38)/2 -> 0 | Q39: =+SUM(Q7:Q38)/2 -> 0 | R39: =+SUM(R7:R38)/2 -> 4 | S39: =+SUM(S7:S38)/2 -> 0.59333333 | T39: =+SUM(T7:T38)/2 -> 175 | V39: =+SUM(V7:V38)/2 -> 69.324167
A41: Prepared By: | H41: Checked By | R41: Acknowledge By:
A47: …........./……....../…........... | H47: …........./……....../…........... | R47: …........./……....../…...........

Sheet 04
A2: Stock Inventory Report of JULY 2026
S4: Date | T4: =+'03'!T4+1 -> 45842 | W4: Sale Report
A5: Nº | B5: Item Name | D5: Par Stock | E5: Opening | H5: Request | K5: In Stock | N5: Lost /Spoil | O5: Transfer out | P5: Cost of FOC | Q5: Cost of Sale | R5: Consumption | S5: Cost of Sale | T5: Closing
B6: English | C6: Khmer | E6: ដើមគ្រា | H6: បើកចូល | K6: ទំនិញមានក្នុងស្តុក | N6: ខូច/បាត់ | O6: ផ្ទេរចេញ | P6: ថ្លៃដើមព្រី | Q6: ថ្លៃដើមលក់ | R6: ថ្លៃដើមលក់ | S6: ថ្លៃដើមលក់ | T6: ចុងគ្រា | W6: Daily | AA6: Monthly
B7: ='01'!B7 -> Soft Drink | C7: ភេសជ្ជៈ | E7: Qtt | F7: U.P | G7: Amount | H7: Qtt | I7: U.P | J7: Amount | K7: Qtt | L7: U.P | M7: Amount | N7: Qtt | O7: Amount | P7: Qtt | Q7: Amount | R7: Qtt | S7: Amount | T7: Qtt | U7: U.P | V7: Amount | Y7: Qty | Z7: Amount | AA7: Qty | AB7: Amount
A8: 1 | B8: ='01'!B8 -> Cocacola Classic 330ml (24cans) | C8: ='01'!C8 -> កូកា ក្លាស៊ិក (កំប៉ុង៣៣០មម) | D8: ='01'!D8 -> 48 | E8: =+'03'!T8 -> 1 | F8: =+'03'!U8 -> 0.3625 | G8: =+'03'!V8 -> 0.3625 | J8: =+H8*I8 -> 0 | K8: =+E8+H8 -> 1 | L8: =IF(K8=0,,M8/K8) -> 0.3625 | M8: =+J8+G8 -> 0.3625 | O8: =+N8*L8 -> 0 | Q8: =+P8*L8 -> 0 | R8: 3 | S8: =+R8*L8 -> 1.0875 | T8: =+K8-N8-P8-R8 -> -2 | U8: =IF(T8=0,,V8/T8) -> 0.3625 | V8: =+T8*L8 -> -0.725 | W8: =+$B$8 -> Cocacola Classic 330ml (24cans) | Y8: =+$R$8 -> 3 | Z8: =+Y8*1 -> 3 | AA8: =+Y8+'03'!AB8 -> 3 | AB8: =+Z8+'03'!AB8 -> 3
A9: =+A8+1 -> 2 | B9: ='01'!B9 -> Cocacola Zero 330ml (24cans) | C9: ='01'!C9 -> កូកា សេរ៉ូ (កំប៉ុង៣៣០មម) | D9: ='01'!D9 -> 48 | E9: =+'03'!T9 -> 18 | F9: =+'03'!U9 -> 0.3625 | G9: =+'03'!V9 -> 6.525 | J9: =+H9*I9 -> 0 | K9: =+E9+H9 -> 18 | L9: =IF(K9=0,,M9/K9) -> 0.3625 | M9: =+J9+G9 -> 6.525 | O9: =+N9*L9 -> 0 | Q9: =+P9*L9 -> 0 | S9: =+R9*L9 -> 0 | T9: =+K9-N9-P9-R9 -> 18 | U9: =IF(T9=0,,V9/T9) -> 0.3625 | V9: =+T9*L9 -> 6.525 | W9: =+$B$9 -> Cocacola Zero 330ml (24cans) | Y9: =+$R$9 -> 0 | Z9: =+Y9*1 -> 0 | AA9: =+Y9+'03'!AB9 -> 0 | AB9: =+Z9+'03'!AC9 -> 0
A10: =+A9+1 -> 3 | B10: ='01'!B10 -> Cocacola Light 330ml (24cans) | C10: ='01'!C10 -> កូកា ឡៃ (កំប៉ុង៣៣០មម) | D10: ='01'!D10 -> 48 | E10: =+'03'!T10 -> 11 | F10: =+'03'!U10 -> 0.3625 | G10: =+'03'!V10 -> 3.9875 | J10: =+H10*I10 -> 0 | K10: =+E10+H10 -> 11 | L10: =IF(K10=0,,M10/K10) -> 0.3625 | M10: =+J10+G10 -> 3.9875 | O10: =+N10*L10 -> 0 | Q10: =+P10*L10 -> 0 | R10: 1 | S10: =+R10*L10 -> 0.3625 | T10: =+K10-N10-P10-R10 -> 10 | U10: =IF(T10=0,,V10/T10) -> 0.3625 | V10: =+T10*L10 -> 3.625 | W10: =+$B$10 -> Cocacola Light 330ml (24cans) | Y10: =+$R$10 -> 1 | Z10: =+Y10*1 -> 1 | AA10: =+Y10+'03'!AB10 -> 1 | AB10: =+Z10+'03'!AC10 -> 1
A11: =+A10+1 -> 4 | B11: ='01'!B11 -> Sprite 330ml (24cans) | C11: ='01'!C11 -> ស្ព្រៃ (កំប៉ុង៣៣០មម) | D11: ='01'!D11 -> 48 | E11: =+'03'!T11 -> 2 | F11: =+'03'!U11 -> 0.3625 | G11: =+'03'!V11 -> 0.725 | J11: =+H11*I11 -> 0 | K11: =+E11+H11 -> 2 | L11: =IF(K11=0,,M11/K11) -> 0.3625 | M11: =+J11+G11 -> 0.725 | O11: =+N11*L11 -> 0 | Q11: =+P11*L11 -> 0 | S11: =+R11*L11 -> 0 | T11: =+K11-N11-P11-R11 -> 2 | U11: =IF(T11=0,,V11/T11) -> 0.3625 | V11: =+T11*L11 -> 0.725 | W11: =+$B$11 -> Sprite 330ml (24cans) | Y11: =+$R$11 -> 0 | Z11: =+Y11*1 -> 0 | AA11: =+Y11+'03'!AB11 -> 0 | AB11: =+Z11+'03'!AC11 -> 0
A12: =+A11+1 -> 5 | B12: ='01'!B12 -> Schweppes Soda Water 330ml (24cans) | C12: ='01'!C12 -> ទឹកសូដា (កំប៉ុង៣៣០មម) | D12: ='01'!D12 -> 48 | E12: =+'03'!T12 -> 14 | F12: =+'03'!U12 -> 0.3625 | G12: =+'03'!V12 -> 5.075 | J12: =+H12*I12 -> 0 | K12: =+E12+H12 -> 14 | L12: =IF(K12=0,,M12/K12) -> 0.3625 | M12: =+J12+G12 -> 5.075 | O12: =+N12*L12 -> 0 | Q12: =+P12*L12 -> 0 | R12: 1 | S12: =+R12*L12 -> 0.3625 | T12: =+K12-N12-P12-R12 -> 13 | U12: =IF(T12=0,,V12/T12) -> 0.3625 | V12: =+T12*L12 -> 4.7125 | W12: =+$B$12 -> Schweppes Soda Water 330ml (24cans) | Y12: =+$R$12 -> 1 | Z12: =+Y12*1 -> 1 | AA12: =+Y12+'03'!AB12 -> 1 | AB12: =+Z12+'03'!AC12 -> 1
A13: =+A12+1 -> 6 | B13: ='01'!B13 -> Schweppes Tonic Water 330ml (24cans) | C13: ='01'!C13 -> ទឹកតូនិច (កំប៉ុង៣៣០មម) | D13: ='01'!D13 -> 48 | E13: =+'03'!T13 -> 19 | F13: =+'03'!U13 -> 0.3625 | G13: =+'03'!V13 -> 6.8875 | J13: =+H13*I13 -> 0 | K13: =+E13+H13 -> 19 | L13: =IF(K13=0,,M13/K13) -> 0.3625 | M13: =+J13+G13 -> 6.8875 | O13: =+N13*L13 -> 0 | Q13: =+P13*L13 -> 0 | S13: =+R13*L13 -> 0 | T13: =+K13-N13-P13-R13 -> 19 | U13: =IF(T13=0,,V13/T13) -> 0.3625 | V13: =+T13*L13 -> 6.8875 | W13: =+$B$13 -> Schweppes Tonic Water 330ml (24cans) | Y13: =+$R$13 -> 0 | Z13: =+Y13*1 -> 0 | AA13: =+Y13+'03'!AB13 -> 0 | AB13: =+Z13+'03'!AC13 -> 0
A14: =+A13+1 -> 7 | B14: ='01'!B14 -> Schweppes Ginger Ale 330ml (24cans) | C14: ='01'!C14 -> ទឹក Ginger ale (កំប៉ុង៣៣០មម) | D14: ='01'!D14 -> 48 | E14: =+'03'!T14 -> 20 | F14: =+'03'!U14 -> 0.3625 | G14: =+'03'!V14 -> 7.25 | J14: =+H14*I14 -> 0 | K14: =+E14+H14 -> 20 | L14: =IF(K14=0,,M14/K14) -> 0.3625 | M14: =+J14+G14 -> 7.25 | O14: =+N14*L14 -> 0 | Q14: =+P14*L14 -> 0 | R14: 2 | S14: =+R14*L14 -> 0.725 | T14: =+K14-N14-P14-R14 -> 18 | U14: =IF(T14=0,,V14/T14) -> 0.3625 | V14: =+T14*L14 -> 6.525 | W14: =+$B$14 -> Schweppes Ginger Ale 330ml (24cans) | Y14: =+$R$14 -> 2 | Z14: =+Y14*1 -> 2 | AA14: =+Y14+'03'!AB14 -> 2 | AB14: =+Z14+'03'!AC14 -> 2
B15: ='01'!B15 -> TOTAL SOFT DRINK | C15: ='01'!C15 -> 0 | D15: ='01'!D15 -> 336 | E15: =+SUM(E8:E14) -> 85 | G15: =+SUM(G8:G14) -> 30.8125 | H15: =+SUM(H8:H14) -> 0 | J15: =+SUM(J8:J14) -> 0 | K15: =+SUM(K8:K14) -> 85 | M15: =+SUM(M8:M14) -> 30.8125 | N15: =+SUM(N8:N14) -> 0 | O15: =+SUM(O8:O14) -> 0 | P15: =+SUM(P8:P14) -> 0 | Q15: =+SUM(Q8:Q14) -> 0 | R15: =+SUM(R8:R14) -> 7 | S15: =+SUM(S8:S14) -> 2.5375 | T15: =+SUM(T8:T14) -> 78 | V15: =+SUM(V8:V14) -> 28.275 | W15: =+$B$17 -> Dasani 500ml (24 Btl) | Y15: =+$R$17 -> 3 | Z15: =+Y15*0.5 -> 1.5 | AA15: =+Y15+'03'!AB15 -> 8 | AB15: =+Z15+'03'!AC15 -> 4
B16: ='01'!B16 -> Water | C16: ='01'!C16 -> 0 | D16: ='01'!D16 -> 0 | W16: =+$B$20 -> TIGER BEER 330ml CAN | Y16: =+$R$20 -> 0 | Z16: =+Y16*1.25 -> 0 | AA16: =+Y16+'03'!AB16 -> 0 | AB16: =+Z16+'03'!AC16 -> 0
A17: =+A14+1 -> 8 | B17: ='01'!B17 -> Dasani 500ml (24 Btl) | C17: ='01'!C17 -> 0 | D17: ='01'!D17 -> 48 | E17: =+'03'!T17 -> 29 | F17: =+'03'!U17 -> 0.14833333 | G17: =+'03'!V17 -> 4.3016667 | J17: =+H17*I17 -> 0 | K17: =+E17+H17 -> 29 | L17: =IF(K17=0,,M17/K17) -> 0.14833333 | M17: =+J17+G17 -> 4.3016667 | O17: =+N17*L17 -> 0 | Q17: =+P17*L17 -> 0 | R17: 3 | S17: =+R17*L17 -> 0.445 | T17: =+K17-N17-P17-R17 -> 26 | U17: =IF(T17=0,,V17/T17) -> 0.14833333 | V17: =+T17*L17 -> 3.8566667 | W17: =+$B$21 -> Heineken 330ml CAN | Y17: =+$R$21 -> 0 | Z17: =+Y17*1.25 -> 0 | AA17: =+Y17+'03'!AB17 -> 0 | AB17: =+Z17+'03'!AC17 -> 0
B18: ='01'!B18 -> TOTAL Water | C18: ='01'!C18 -> 0 | D18: ='01'!D18 -> 48 | E18: =+E17 -> 29 | G18: =+G17 -> 4.3016667 | H18: =+H17 -> 0 | J18: =+J17 -> 0 | K18: =+K17 -> 29 | M18: =+M17 -> 4.3016667 | N18: =+N17 -> 0 | O18: =+O17 -> 0 | P18: =+P17 -> 0 | Q18: =+Q17 -> 0 | R18: =+R17 -> 3 | S18: =+S17 -> 0.445 | T18: =+T17 -> 26 | V18: =+V17 -> 3.8566667 | Y18: =+$R$22 -> 0 | Z18: =+Y18*1 -> 0 | AA18: =+Y18+'03'!AB18 -> 0 | AB18: =+Z18+'03'!AB18 -> 0
B19: ='01'!B19 -> Beer | C19: ='01'!C19 -> 0 | D19: ='01'!D19 -> 0 | Y19: =+$R$23 -> 0 | Z19: =+Y19*1 -> 0 | AA19: =+Y19+'03'!AB19 -> 0 | AB19: =+Z19+'03'!AB19 -> 0
A20: =+A19+1 -> 1 | B20: ='01'!B20 -> TIGER BEER 330ml CAN | C20: ='01'!C20 -> ស្រាបៀរថៃហ្គ័រ (កំប៉ុង ៣៣០មល) | D20: ='01'!D20 -> 48 | E20: =+'03'!T20 -> 32 | F20: =+'03'!U20 -> 0.48 | G20: =+'03'!V20 -> 15.36 | J20: =+H20*I20 -> 0 | K20: =+E20+H20 -> 32 | L20: =IF(K20=0,,M20/K20) -> 0.48 | M20: =+J20+G20 -> 15.36 | O20: =+N20*L20 -> 0 | Q20: =+P20*L20 -> 0 | S20: =+R20*L20 -> 0 | T20: =+K20-N20-P20-R20 -> 32 | U20: =IF(T20=0,,V20/T20) -> 0.48 | V20: =+T20*L20 -> 15.36 | W20: TOTAL | Y20: =+SUM(Y8:Y19) -> 10 | Z20: =+SUM(Z8:Z19) -> 8.5 | AA20: =+SUM(AA8:AA19) -> 15 | AB20: =+SUM(AB8:AB19) -> 11
A21: =+A20+1 -> 2 | B21: ='01'!B21 -> Heineken 330ml CAN | C21: ='01'!C21 -> ស្រាបៀរហេន័រឃិន (កំប៉ុង ៣៣០មល) | D21: ='01'!D21 -> 48 | E21: =+'03'!T21 -> 29 | F21: =+'03'!U21 -> 0.65 | G21: =+'03'!V21 -> 18.85 | J21: =+H21*I21 -> 0 | K21: =+E21+H21 -> 29 | L21: =IF(K21=0,,M21/K21) -> 0.65 | M21: =+J21+G21 -> 18.85 | O21: =+N21*L21 -> 0 | Q21: =+P21*L21 -> 0 | S21: =+R21*L21 -> 0 | T21: =+K21-N21-P21-R21 -> 29 | U21: =IF(T21=0,,V21/T21) -> 0.65 | V21: =+T21*L21 -> 18.85
A22: =+A21+1 -> 3 | B22: ='01'!B22 -> 0 | C22: ='01'!C22 -> 0 | D22: ='01'!D22 -> 0 | E22: =+'03'!T22 -> 0 | F22: =+'03'!U22 -> 0 | G22: =+'03'!V22 -> 0 | J22: =+H22*I22 -> 0 | K22: =+E22+H22 -> 0 | L22: =IF(K22=0,,M22/K22) -> 0 | M22: =+J22+G22 -> 0 | O22: =+N22*L22 -> 0 | Q22: =+P22*L22 -> 0 | S22: =+R22*L22 -> 0 | T22: =+K22-N22-P22-R22 -> 0 | U22: =IF(T22=0,,V22/T22) -> 0 | V22: =+T22*L22 -> 0
A23: =+A22+1 -> 4 | B23: ='01'!B23 -> 0 | C23: ='01'!C23 -> 0 | D23: ='01'!D23 -> 0 | E23: =+'03'!T23 -> 0 | F23: =+'03'!U23 -> 0 | G23: =+'03'!V23 -> 0 | J23: =+H23*I23 -> 0 | K23: =+E23+H23 -> 0 | L23: =IF(K23=0,,M23/K23) -> 0 | M23: =+J23+G23 -> 0 | O23: =+N23*L23 -> 0 | Q23: =+P23*L23 -> 0 | S23: =+R23*L23 -> 0 | T23: =+K23-N23-P23-R23 -> 0 | U23: =IF(T23=0,,V23/T23) -> 0 | V23: =+T23*L23 -> 0
A24: =+A23+1 -> 5 | B24: ='01'!B24 -> 0 | C24: ='01'!C24 -> 0 | D24: ='01'!D24 -> 0 | E24: =+'03'!T24 -> 0 | F24: =+'03'!U24 -> 0 | G24: =+'03'!V24 -> 0 | J24: =+H24*I24 -> 0 | K24: =+E24+H24 -> 0 | L24: =IF(K24=0,,M24/K24) -> 0 | M24: =+J24+G24 -> 0 | O24: =+N24*L24 -> 0 | Q24: =+P24*L24 -> 0 | S24: =+R24*L24 -> 0 | T24: =+K24-N24-P24-R24 -> 0 | U24: =IF(T24=0,,V24/T24) -> 0 | V24: =+T24*L24 -> 0
A25: =+A24+1 -> 6 | D25: ='01'!D25 -> 0 | E25: =+'03'!T25 -> 0 | F25: =+'03'!U25 -> 0 | G25: =+'03'!V25 -> 0 | J25: =+H25*I25 -> 0 | K25: =+E25+H25 -> 0 | L25: =IF(K25=0,,M25/K25) -> 0 | M25: =+J25+G25 -> 0 | O25: =+N25*L25 -> 0 | Q25: =+P25*L25 -> 0 | S25: =+R25*L25 -> 0 | T25: =+K25-N25-P25-R25 -> 0 | U25: =IF(T25=0,,V25/T25) -> 0 | V25: =+T25*L25 -> 0
A26: =+A25+1 -> 7 | D26: ='01'!D26 -> 0 | E26: =+'03'!T26 -> 0 | F26: =+'03'!U26 -> 0 | G26: =+'03'!V26 -> 0 | J26: =+H26*I26 -> 0 | K26: =+E26+H26 -> 0 | L26: =IF(K26=0,,M26/K26) -> 0 | M26: =+J26+G26 -> 0 | O26: =+N26*L26 -> 0 | Q26: =+P26*L26 -> 0 | S26: =+R26*L26 -> 0 | T26: =+K26-N26-P26-R26 -> 0 | U26: =IF(T26=0,,V26/T26) -> 0 | V26: =+T26*L26 -> 0
A27: =+A26+1 -> 8 | D27: ='01'!D27 -> 0 | E27: =+'03'!T27 -> 0 | F27: =+'03'!U27 -> 0 | G27: =+'03'!V27 -> 0 | J27: =+H27*I27 -> 0 | K27: =+E27+H27 -> 0 | L27: =IF(K27=0,,M27/K27) -> 0 | M27: =+J27+G27 -> 0 | O27: =+N27*L27 -> 0 | Q27: =+P27*L27 -> 0 | S27: =+R27*L27 -> 0 | T27: =+K27-N27-P27-R27 -> 0 | U27: =IF(T27=0,,V27/T27) -> 0 | V27: =+T27*L27 -> 0
A28: =+A27+1 -> 9 | D28: ='01'!D28 -> 0 | E28: =+'03'!T28 -> 0 | F28: =+'03'!U28 -> 0 | G28: =+'03'!V28 -> 0 | J28: =+H28*I28 -> 0 | K28: =+E28+H28 -> 0 | L28: =IF(K28=0,,M28/K28) -> 0 | M28: =+J28+G28 -> 0 | O28: =+N28*L28 -> 0 | Q28: =+P28*L28 -> 0 | S28: =+R28*L28 -> 0 | T28: =+K28-N28-P28-R28 -> 0 | U28: =IF(T28=0,,V28/T28) -> 0 | V28: =+T28*L28 -> 0
A29: =+A28+1 -> 10 | D29: ='01'!D29 -> 0 | E29: =+'03'!T29 -> 0 | F29: =+'03'!U29 -> 0 | G29: =+'03'!V29 -> 0 | J29: =+H29*I29 -> 0 | K29: =+E29+H29 -> 0 | L29: =IF(K29=0,,M29/K29) -> 0 | M29: =+J29+G29 -> 0 | O29: =+N29*L29 -> 0 | Q29: =+P29*L29 -> 0 | S29: =+R29*L29 -> 0 | T29: =+K29-N29-P29-R29 -> 0 | U29: =IF(T29=0,,V29/T29) -> 0 | V29: =+T29*L29 -> 0
A30: =+A29+1 -> 11 | D30: ='01'!D30 -> 0 | E30: =+'03'!T30 -> 0 | F30: =+'03'!U30 -> 0 | G30: =+'03'!V30 -> 0 | J30: =+H30*I30 -> 0 | K30: =+E30+H30 -> 0 | L30: =IF(K30=0,,M30/K30) -> 0 | M30: =+J30+G30 -> 0 | O30: =+N30*L30 -> 0 | Q30: =+P30*L30 -> 0 | S30: =+R30*L30 -> 0 | T30: =+K30-N30-P30-R30 -> 0 | U30: =IF(T30=0,,V30/T30) -> 0 | V30: =+T30*L30 -> 0
A31: =+A30+1 -> 12 | D31: ='01'!D31 -> 0 | E31: =+'03'!T31 -> 0 | F31: =+'03'!U31 -> 0 | G31: =+'03'!V31 -> 0 | J31: =+H31*I31 -> 0 | K31: =+E31+H31 -> 0 | L31: =IF(K31=0,,M31/K31) -> 0 | M31: =+J31+G31 -> 0 | O31: =+N31*L31 -> 0 | Q31: =+P31*L31 -> 0 | S31: =+R31*L31 -> 0 | T31: =+K31-N31-P31-R31 -> 0 | U31: =IF(T31=0,,V31/T31) -> 0 | V31: =+T31*L31 -> 0
A32: =+A31+1 -> 13 | D32: ='01'!D32 -> 0 | E32: =+'03'!T32 -> 0 | F32: =+'03'!U32 -> 0 | G32: =+'03'!V32 -> 0 | J32: =+H32*I32 -> 0 | K32: =+E32+H32 -> 0 | L32: =IF(K32=0,,M32/K32) -> 0 | M32: =+J32+G32 -> 0 | O32: =+N32*L32 -> 0 | Q32: =+P32*L32 -> 0 | S32: =+R32*L32 -> 0 | T32: =+K32-N32-P32-R32 -> 0 | U32: =IF(T32=0,,V32/T32) -> 0 | V32: =+T32*L32 -> 0
A33: =+A32+1 -> 14 | D33: ='01'!D33 -> 0 | E33: =+'03'!T33 -> 0 | F33: =+'03'!U33 -> 0 | G33: =+'03'!V33 -> 0 | J33: =+H33*I33 -> 0 | K33: =+E33+H33 -> 0 | L33: =IF(K33=0,,M33/K33) -> 0 | M33: =+J33+G33 -> 0 | O33: =+N33*L33 -> 0 | Q33: =+P33*L33 -> 0 | S33: =+R33*L33 -> 0 | T33: =+K33-N33-P33-R33 -> 0 | U33: =IF(T33=0,,V33/T33) -> 0 | V33: =+T33*L33 -> 0
A34: =+A33+1 -> 15 | D34: ='01'!D34 -> 0 | E34: =+'03'!T34 -> 0 | F34: =+'03'!U34 -> 0 | G34: =+'03'!V34 -> 0 | J34: =+H34*I34 -> 0 | K34: =+E34+H34 -> 0 | L34: =IF(K34=0,,M34/K34) -> 0 | M34: =+J34+G34 -> 0 | O34: =+N34*L34 -> 0 | Q34: =+P34*L34 -> 0 | S34: =+R34*L34 -> 0 | T34: =+K34-N34-P34-R34 -> 0 | U34: =IF(T34=0,,V34/T34) -> 0 | V34: =+T34*L34 -> 0
A35: =+A34+1 -> 16 | D35: ='01'!D35 -> 0 | E35: =+'03'!T35 -> 0 | F35: =+'03'!U35 -> 0 | G35: =+'03'!V35 -> 0 | J35: =+H35*I35 -> 0 | K35: =+E35+H35 -> 0 | L35: =IF(K35=0,,M35/K35) -> 0 | M35: =+J35+G35 -> 0 | O35: =+N35*L35 -> 0 | Q35: =+P35*L35 -> 0 | S35: =+R35*L35 -> 0 | T35: =+K35-N35-P35-R35 -> 0 | U35: =IF(T35=0,,V35/T35) -> 0 | V35: =+T35*L35 -> 0
A36: =+A35+1 -> 17 | D36: ='01'!D36 -> 0 | E36: =+'03'!T36 -> 0 | F36: =+'03'!U36 -> 0 | G36: =+'03'!V36 -> 0 | J36: =+H36*I36 -> 0 | K36: =+E36+H36 -> 0 | L36: =IF(K36=0,,M36/K36) -> 0 | M36: =+J36+G36 -> 0 | O36: =+N36*L36 -> 0 | Q36: =+P36*L36 -> 0 | S36: =+R36*L36 -> 0 | T36: =+K36-N36-P36-R36 -> 0 | U36: =IF(T36=0,,V36/T36) -> 0 | V36: =+T36*L36 -> 0
A37: =+A36+1 -> 18 | D37: ='01'!D37 -> 0 | E37: =+'03'!T37 -> 0 | F37: =+'03'!U37 -> 0 | G37: =+'03'!V37 -> 0 | J37: =+H37*I37 -> 0 | K37: =+E37+H37 -> 0 | L37: =IF(K37=0,,M37/K37) -> 0 | M37: =+J37+G37 -> 0 | O37: =+N37*L37 -> 0 | Q37: =+P37*L37 -> 0 | S37: =+R37*L37 -> 0 | T37: =+K37-N37-P37-R37 -> 0 | U37: =IF(T37=0,,V37/T37) -> 0 | V37: =+T37*L37 -> 0
B38: ='01'!B38 -> TOTAL BEER | C38: ='01'!C38 -> 0 | D38: ='01'!D38 -> 96 | E38: =+SUM(E20:E24) -> 61 | G38: =+SUM(G20:G37) -> 34.21 | H38: =+SUM(H20:H37) -> 0 | J38: =+SUM(J20:J37) -> 0 | K38: =+SUM(K20:K37) -> 61 | M38: =+SUM(M20:M37) -> 34.21 | N38: =+SUM(N20:N37) -> 0 | O38: =+SUM(O20:O37) -> 0 | P38: =+SUM(P20:P37) -> 0 | Q38: =+SUM(Q20:Q37) -> 0 | R38: =+SUM(R20:R37) -> 0 | S38: =+SUM(S20:S37) -> 0 | T38: =+SUM(T20:T37) -> 61 | V38: =+SUM(V20:V37) -> 34.21
B39: ='01'!B39 -> Grand TOTAL | C39: ='01'!C39 -> 0 | D39: ='01'!D39 -> 480 | E39: =+SUM(E7:E38)/2 -> 175 | G39: =+SUM(G7:G38)/2 -> 69.324167 | H39: =+SUM(H7:H38)/2 -> 0 | J39: =+SUM(J7:J38)/2 -> 0 | K39: =+SUM(K7:K38)/2 -> 175 | M39: =+SUM(M7:M38)/2 -> 69.324167 | N39: =+SUM(N7:N38)/2 -> 0 | O39: =+SUM(O7:O38)/2 -> 0 | P39: =+SUM(P7:P38)/2 -> 0 | Q39: =+SUM(Q7:Q38)/2 -> 0 | R39: =+SUM(R7:R38)/2 -> 10 | S39: =+SUM(S7:S38)/2 -> 2.9825 | T39: =+SUM(T7:T38)/2 -> 165 | V39: =+SUM(V7:V38)/2 -> 66.341667
A41: Prepared By: | H41: Checked By | R41: Acknowledge By:
A47: …........./……....../…........... | H47: …........./……....../…........... | R47: …........./……....../…...........

Sheet 05
A2: Stock Inventory Report of JULY 2026
S4: Date | T4: =+'04'!T4+1 -> 45843 | W4: Sale Report
A5: Nº | B5: Item Name | D5: Par Stock | E5: Opening | H5: Request | K5: In Stock | N5: Lost /Spoil | O5: Transfer out | P5: Cost of FOC | Q5: Cost of Sale | R5: Consumption | S5: Cost of Sale | T5: Closing
B6: English | C6: Khmer | E6: ដើមគ្រា | H6: បើកចូល | K6: ទំនិញមានក្នុងស្តុក | N6: ខូច/បាត់ | O6: ផ្ទេរចេញ | P6: ថ្លៃដើមព្រី | Q6: ថ្លៃដើមលក់ | R6: ថ្លៃដើមលក់ | S6: ថ្លៃដើមលក់ | T6: ចុងគ្រា | W6: Daily | AA6: Monthly
B7: ='01'!B7 -> Soft Drink | C7: ភេសជ្ជៈ | E7: Qtt | F7: U.P | G7: Amount | H7: Qtt | I7: U.P | J7: Amount | K7: Qtt | L7: U.P | M7: Amount | N7: Qtt | O7: Amount | P7: Qtt | Q7: Amount | R7: Qtt | S7: Amount | T7: Qtt | U7: U.P | V7: Amount | Y7: Qty | Z7: Amount | AA7: Qty | AB7: Amount
A8: 1 | B8: ='01'!B8 -> Cocacola Classic 330ml (24cans) | C8: ='01'!C8 -> កូកា ក្លាស៊ិក (កំប៉ុង៣៣០មម) | D8: ='01'!D8 -> 48 | E8: =+'04'!T8 -> -2 | F8: =+'04'!U8 -> 0.3625 | G8: =+'04'!V8 -> -0.725 | J8: =+H8*I8 -> 0 | K8: =+E8+H8 -> -2 | L8: =IF(K8=0,,M8/K8) -> 0.3625 | M8: =+J8+G8 -> -0.725 | O8: =+N8*L8 -> 0 | Q8: =+P8*L8 -> 0 | S8: =+R8*L8 -> 0 | T8: =+K8-N8-P8-R8 -> -2 | U8: =IF(T8=0,,V8/T8) -> 0.3625 | V8: =+T8*L8 -> -0.725 | W8: =+$B$8 -> Cocacola Classic 330ml (24cans) | Y8: =+$R$8 -> 0 | Z8: =+Y8*1 -> 0 | AA8: =+Y8+'04'!AA8 -> 3 | AB8: =+Z8+'04'!AB8 -> 3
A9: =+A8+1 -> 2 | B9: ='01'!B9 -> Cocacola Zero 330ml (24cans) | C9: ='01'!C9 -> កូកា សេរ៉ូ (កំប៉ុង៣៣០មម) | D9: ='01'!D9 -> 48 | E9: =+'04'!T9 -> 18 | F9: =+'04'!U9 -> 0.3625 | G9: =+'04'!V9 -> 6.525 | J9: =+H9*I9 -> 0 | K9: =+E9+H9 -> 18 | L9: =IF(K9=0,,M9/K9) -> 0.3625 | M9: =+J9+G9 -> 6.525 | O9: =+N9*L9 -> 0 | Q9: =+P9*L9 -> 0 | S9: =+R9*L9 -> 0 | T9: =+K9-N9-P9-R9 -> 18 | U9: =IF(T9=0,,V9/T9) -> 0.3625 | V9: =+T9*L9 -> 6.525 | W9: =+$B$9 -> Cocacola Zero 330ml (24cans) | Y9: =+$R$9 -> 0 | Z9: =+Y9*1 -> 0 | AA9: =+Y9+'04'!AA9 -> 0 | AB9: =+Z9+'04'!AB9 -> 0
